Workbook

Sheet Dashboard
B1: DASHBOARD DE COBRANZAS — CENTIC SAS
B2: Control de cartera por cobrar · Cursos y certificaciones
B3: Los indicadores se recalculan automáticamente a partir de la hoja "Ventas". Última actualización: fórmulas en vivo.
B5: CARTERA TOTAL PENDIENTE | E5: N° DE REGISTROS CON SALDO | H5: SALDO PROMEDIO POR REGISTRO | K5: % CARTERA "AL DÍA" | M5: % CARTERA EN GESTIÓN / RIESGO
B7: =TEXT(SUM(Ventas!M3:M306),"$ #,##0") -> $ 55,986,967 | E7: =COUNT(Ventas!M3:M306) -> 64 | H7: =TEXT(AVERAGE(Ventas!M3:M306),"$ #,##0") -> $ 874,796 | K7: =TEXT(COUNTIF(Ventas!O3:O306,"Al día")/COUNT(Ventas!M3:M306),"0%") -> 11% | M7: =TEXT(1-COUNTIF(Ventas!O3:O306,"Al día")/COUNT(Ventas!M3:M306),"0%") -> 89%
B11: ="Mayor saldo individual: " & INDEX(Ventas!B3:B306,MATCH(1,Ventas!R3:R306,0)) & " — $" & TEXT(INDEX(Ventas!M3:M306,MATCH(1,Ventas!R3:R306,0)),"#,##0") & " · Vendedor: " & INDEX(Ventas!N3:N306,MATCH(1,Ventas!R3:R306,0)) -> Mayor saldo individual: Gabriel Enrique Moreno Pérez — $3,150,000 · Vendedor: Sebas
B13: ① Cartera por estado de gestión | H13: ⑤ Top 10 registros con mayor saldo pendiente
B14: Estado | C14: Cartera ($) | D14: N° registros | H14: Cliente | I14: Saldo ($) | J14: Vendedor
B15: Al día | C15: =SUMIF(Ventas!$O$3:$O$306,B15,Ventas!$M$3:$M$306) -> 6040000 | D15: =COUNTIF(Ventas!$O$3:$O$306,B15) -> 7 | H15: =IFERROR(INDEX(Ventas!$B$3:$B$306,MATCH(1,Ventas!$R$3:$R$306,0)),"") -> Gabriel Enrique Moreno Pérez | I15: =IFERROR(INDEX(Ventas!$M$3:$M$306,MATCH(1,Ventas!$R$3:$R$306,0)),"") -> 3150000 | J15: =IFERROR(INDEX(Ventas!$N$3:$N$306,MATCH(1,Ventas!$R$3:$R$306,0)),"") -> Sebas
B16: Pendiente / Compromiso | C16: =SUMIF(Ventas!$O$3:$O$306,B16,Ventas!$M$3:$M$306) -> 9069967 | D16: =COUNTIF(Ventas!$O$3:$O$306,B16) -> 11 | H16: =IFERROR(INDEX(Ventas!$B$3:$B$306,MATCH(2,Ventas!$R$3:$R$306,0)),"") -> Jhon Isaias Muñoz Remolina | I16: =IFERROR(INDEX(Ventas!$M$3:$M$306,MATCH(2,Ventas!$R$3:$R$306,0)),"") -> 2390000 | J16: =IFERROR(INDEX(Ventas!$N$3:$N$306,MATCH(2,Ventas!$R$3:$R$306,0)),"") -> Ximena
B17: Sin respuesta / Inactivo | C17: =SUMIF(Ventas!$O$3:$O$306,B17,Ventas!$M$3:$M$306) -> 5100000 | D17: =COUNTIF(Ventas!$O$3:$O$306,B17) -> 2 | H17: =IFERROR(INDEX(Ventas!$B$3:$B$306,MATCH(3,Ventas!$R$3:$R$306,0)),"") -> Jhon Edison Puerto Jiménez | I17: =IFERROR(INDEX(Ventas!$M$3:$M$306,MATCH(3,Ventas!$R$3:$R$306,0)),"") -> 2050000 | J17: =IFERROR(INDEX(Ventas!$N$3:$N$306,MATCH(3,Ventas!$R$3:$R$306,0)),"") -> Carolina
B18: Sin gestionar | C18: =SUMIF(Ventas!$O$3:$O$306,B18,Ventas!$M$3:$M$306) -> 35777000 | D18: =COUNTIF(Ventas!$O$3:$O$306,B18) -> 44 | H18: =IFERROR(INDEX(Ventas!$B$3:$B$306,MATCH(4,Ventas!$R$3:$R$306,0)),"") -> Cesar Augusto Ramirez | I18: =IFERROR(INDEX(Ventas!$M$3:$M$306,MATCH(4,Ventas!$R$3:$R$306,0)),"") -> 1950000 | J18: =IFERROR(INDEX(Ventas!$N$3:$N$306,MATCH(4,Ventas!$R$3:$R$306,0)),"") -> Ximena
H19: =IFERROR(INDEX(Ventas!$B$3:$B$306,MATCH(5,Ventas!$R$3:$R$306,0)),"") -> JOHAN YESID MORENO SARMIENTO | I19: =IFERROR(INDEX(Ventas!$M$3:$M$306,MATCH(5,Ventas!$R$3:$R$306,0)),"") -> 1850000 | J19: =IFERROR(INDEX(Ventas!$N$3:$N$306,MATCH(5,Ventas!$R$3:$R$306,0)),"") -> Carolina
H20: =IFERROR(INDEX(Ventas!$B$3:$B$306,MATCH(6,Ventas!$R$3:$R$306,0)),"") -> Andrea Olarte Trujillo | I20: =IFERROR(INDEX(Ventas!$M$3:$M$306,MATCH(6,Ventas!$R$3:$R$306,0)),"") -> 1750000 | J20: =IFERROR(INDEX(Ventas!$N$3:$N$306,MATCH(6,Ventas!$R$3:$R$306,0)),"") -> Sebas
B21: ② Cartera por vendedor | H21: =IFERROR(INDEX(Ventas!$B$3:$B$306,MATCH(7,Ventas!$R$3:$R$306,0)),"") -> Natalia Fernanda Huertas Rodriguez | I21: =IFERROR(INDEX(Ventas!$M$3:$M$306,MATCH(7,Ventas!$R$3:$R$306,0)),"") -> 1600000 | J21: =IFERROR(INDEX(Ventas!$N$3:$N$306,MATCH(7,Ventas!$R$3:$R$306,0)),"") -> Ximena
B22: Vendedor | C22: Cartera ($) | D22: N° registros | H22: =IFERROR(INDEX(Ventas!$B$3:$B$306,MATCH(8,Ventas!$R$3:$R$306,0)),"") -> Niver Alberto López Gómez | I22: =IFERROR(INDEX(Ventas!$M$3:$M$306,MATCH(8,Ventas!$R$3:$R$306,0)),"") -> 1600000 | J22: =IFERROR(INDEX(Ventas!$N$3:$N$306,MATCH(8,Ventas!$R$3:$R$306,0)),"") -> Carolina
B23: Ximena | C23: =SUMIF(Ventas!$N$3:$N$306,B23,Ventas!$M$3:$M$306) -> 22661967 | D23: =COUNTIF(Ventas!$N$3:$N$306,B23) -> 32 | H23: =IFERROR(INDEX(Ventas!$B$3:$B$306,MATCH(9,Ventas!$R$3:$R$306,0)),"") -> Juan Diego Salcedo García | I23: =IFERROR(INDEX(Ventas!$M$3:$M$306,MATCH(9,Ventas!$R$3:$R$306,0)),"") -> 1500000 | J23: =IFERROR(INDEX(Ventas!$N$3:$N$306,MATCH(9,Ventas!$R$3:$R$306,0)),"") -> Carolina
B24: Carolina | C24: =SUMIF(Ventas!$N$3:$N$306,B24,Ventas!$M$3:$M$306) -> 17915000 | D24: =COUNTIF(Ventas!$N$3:$N$306,B24) -> 19 | H24: =IFERROR(INDEX(Ventas!$B$3:$B$306,MATCH(10,Ventas!$R$3:$R$306,0)),"") -> Mauricio Villate Granados | I24: =IFERROR(INDEX(Ventas!$M$3:$M$306,MATCH(10,Ventas!$R$3:$R$306,0)),"") -> 1470000 | J24: =IFERROR(INDEX(Ventas!$N$3:$N$306,MATCH(10,Ventas!$R$3:$R$306,0)),"") -> Carolina
B25: Sebas | C25: =SUMIF(Ventas!$N$3:$N$306,B25,Ventas!$M$3:$M$306) -> 14410000 | D25: =COUNTIF(Ventas!$N$3:$N$306,B25) -> 12
B28: ③ Cartera por categoría de servicio
B29: Categoría | C29: Cartera ($) | D29: N° registros
B30: ITIL | C30: =SUMIF(Ventas!$P$3:$P$306,B30,Ventas!$M$3:$M$306) -> 16932000 | D30: =COUNTIF(Ventas!$P$3:$P$306,B30) -> 19
B31: ISO 27001 | C31: =SUMIF(Ventas!$P$3:$P$306,B31,Ventas!$M$3:$M$306) -> 4374967 | D31: =COUNTIF(Ventas!$P$3:$P$306,B31) -> 6
B32: ISO 42001 | C32: =SUMIF(Ventas!$P$3:$P$306,B32,Ventas!$M$3:$M$306) -> 800000 | D32: =COUNTIF(Ventas!$P$3:$P$306,B32) -> 2
B33: Otras ISO | C33: =SUMIF(Ventas!$P$3:$P$306,B33,Ventas!$M$3:$M$306) -> 2200000 | D33: =COUNTIF(Ventas!$P$3:$P$306,B33) -> 2
B34: SCRUM | C34: =SUMIF(Ventas!$P$3:$P$306,B34,Ventas!$M$3:$M$306) -> 1735000 | D34: =COUNTIF(Ventas!$P$3:$P$306,B34) -> 3
B35: BRIDGE | C35: =SUMIF(Ventas!$P$3:$P$306,B35,Ventas!$M$3:$M$306) -> 2860000 | D35: =COUNTIF(Ventas!$P$3:$P$306,B35) -> 6
B36: CDS | C36: =SUMIF(Ventas!$P$3:$P$306,B36,Ventas!$M$3:$M$306) -> 3590000 | D36: =COUNTIF(Ventas!$P$3:$P$306,B36) -> 3
B37: TOGAF | C37: =SUMIF(Ventas!$P$3:$P$306,B37,Ventas!$M$3:$M$306) -> 1000000 | D37: =COUNTIF(Ventas!$P$3:$P$306,B37) -> 1
B38: DPI | C38: =SUMIF(Ventas!$P$3:$P$306,B38,Ventas!$M$3:$M$306) -> 1950000 | D38: =COUNTIF(Ventas!$P$3:$P$306,B38) -> 2
B39: DITS | C39: =SUMIF(Ventas!$P$3:$P$306,B39,Ventas!$M$3:$M$306) -> 3150000 | D39: =COUNTIF(Ventas!$P$3:$P$306,B39) -> 1
B40: AGILE | C40: =SUMIF(Ventas!$P$3:$P$306,B40,Ventas!$M$3:$M$306) -> 390000 | D40: =COUNTIF(Ventas!$P$3:$P$306,B40) -> 1
B41: Ciberseguridad | C41: =SUMIF(Ventas!$P$3:$P$306,B41,Ventas!$M$3:$M$306) -> 1350000 | D41: =COUNTIF(Ventas!$P$3:$P$306,B41) -> 2
B42: Sin definir | C42: =SUMIF(Ventas!$P$3:$P$306,B42,Ventas!$M$3:$M$306) -> 15655000 | D42: =COUNTIF(Ventas!$P$3:$P$306,B42) -> 16
B44: ④ Antigüedad de mora (meses)
B45: Rango | C45: Cartera ($) | D45: N° registros
B46: 1-3 meses | C46: =SUMIF(Ventas!$Q$3:$Q$306,B46,Ventas!$M$3:$M$306) -> 0 | D46: =COUNTIF(Ventas!$Q$3:$Q$306,B46) -> 0
B47: 4-6 meses | C47: =SUMIF(Ventas!$Q$3:$Q$306,B47,Ventas!$M$3:$M$306) -> 3507000 | D47: =COUNTIF(Ventas!$Q$3:$Q$306,B47) -> 4
B48: +6 meses | C48: =SUMIF(Ventas!$Q$3:$Q$306,B48,Ventas!$M$3:$M$306) -> 290000 | D48: =COUNTIF(Ventas!$Q$3:$Q$306,B48) -> 1
B49: Sin dato registrado | C49: =SUMIF(Ventas!$Q$3:$Q$306,B49,Ventas!$M$3:$M$306) -> 52189967 | D49: =COUNTIF(Ventas!$Q$3:$Q$306,B49) -> 59
...

Sheet Ventas
A1: ID_Venta | B1: Nombre completo | C1: Fecha del contacto | D1: Vendedor | E1: Servicio | F1: Estado de cobro | G1: % interes de mora | H1: Valor de interes de mora | I1: Total a pagar | J1: Fecha de compromiso de pago | K1: Meses en mora | L1: Estado de cobro2 | M1: AYUDA PARA DASHBOARD — NO EDITAR (se calcula solo)
A2: 1 | B2: Froilán González Roa | C2: 46127 | D2: Carolina | E2: ITIL 4 Fundamentos | F2: Curso y examen | G2: no | H2: no | I2: 890000 | J2: ABONO 5 MAYO | K2: 3 | L2: PAGO AL DIA | M2: Total depurado ($) | N2: Vendedor (normalizado) | O2: Estado cartera (normalizado) | P2: Categoría servicio | Q2: Rango antigüedad mora | R2: Rank saldo (para Top 10)
A3: 2 | B3: Karen Sirley Hernandez Morales | C3: 46107 | D3: Ximena | E3: SCRUM Plus | F3: M+PO | G3: INCREMENTO | H3: 100000 | I3: 290000 | J3: ABONO 1 31 MAR Y ABONO 2 15 ABRIL | K3: 8 | L3: Pendiente | M3: =IF(B3="","",IF(ISNUMBER(I3),I3,IFERROR(VALUE(SUBSTITUTE(SUBSTITUTE(I3,"$",""),".","")),0))) -> 290000 | N3: =IF(B3="","",PROPER(TRIM(D3))) -> Ximena | O3: =IF(B3="","",IF(OR(ISNUMBER(SEARCH("AL DIA",L3)),ISNUMBER(SEARCH("AL DIA",F3))),"Al día",IF(OR(ISNUMBER(SEARCH("QUIETO",L3)),ISNUMBER(SEARCH("QUIETO",F3)),ISNUMBER(SEARCH("ESPERANDO",L3)),ISNUMBER(SEARCH("ESPERANDO",F3))),"Sin respuesta / Inactivo",IF(OR(ISNUMBER(SEARCH("PENDIENTE",L3)),ISNUMBER(SEARCH("PENDIENTE",F3)),ISNUMBER(SEARCH("COMPROMISO",F3)),ISNUMBER(SEARCH("COMPROMISO",L3)),ISNUMBER(SEARCH("PROCESO",F3)),ISNUMBER(SEARCH("LLAMAR",F3)),ISNUMBER(SEARCH("ABONO",J3)),EXACT(L3,"P"),EXACT(F3,"P")),"Pendiente / Compromiso","Sin gestionar")))) -> Pendiente / Compromiso | P3: =IF(B3="","",IF(E3="","Sin definir",IF(ISNUMBER(SEARCH("ITIL",E3)),"ITIL",IF(ISNUMBER(SEARCH("ISO 27001",E3)),"ISO 27001",IF(ISNUMBER(SEARCH("ISO 42001",E3)),"ISO 42001",IF(ISNUMBER(SEARCH("ISO",E3)),"Otras ISO",IF(ISNUMBER(SEARCH("SCRUM",E3)),"SCRUM",IF(ISNUMBER(SEARCH("BRIDGE",E3)),"BRIDGE",IF(ISNUMBER(SEARCH("CDS",E3)),"CDS",IF(ISNUMBER(SEARCH("TOGAF",E3)),"TOGAF",IF(ISNUMBER(SEARCH("DPI",E3)),"DPI",IF(ISNUMBER(SEARCH("DITS",E3)),"DITS",IF(ISNUMBER(SEARCH("AGILE",E3)),"AGILE",IF(ISNUMBER(SEARCH("Ciberseguridad",E3)),"Ciberseguridad","Otros")))))))))))))) -> SCRUM | Q3: =IF(B3="","",IF(ISNUMBER(K3),IF(K3<=3,"1-3 meses",IF(K3<=6,"4-6 meses","+6 meses")),"Sin dato registrado")) -> +6 meses | R3: =IF(OR(B3="",M3=""),"",RANK(M3,$M$3:$M$306)+COUNTIF($M$3:M3,M3)-1) -> 55
A4: 3 | B4: Edgar Enrique Beltran Hernandez | C4: 46107 | D4: Ximena | E4: ITIL 4 Fundamentos | F4: Curso y examen | G4: INCREMENTO | H4: X | I4: 190000 | J4: abono1 27 de marzo hasta 15 mayo | K4: 6 | L4: PAGO AL DIA | M4: =IF(B4="","",IF(ISNUMBER(I4),I4,IFERROR(VALUE(SUBSTITUTE(SUBSTITUTE(I4,"$",""),".","")),0))) -> 190000 | N4: =IF(B4="","",PROPER(TRIM(D4))) -> Ximena | O4: =IF(B4="","",IF(OR(ISNUMBER(SEARCH("AL DIA",L4)),ISNUMBER(SEARCH("AL DIA",F4))),"Al día",IF(OR(ISNUMBER(SEARCH("QUIETO",L4)),ISNUMBER(SEARCH("QUIETO",F4)),ISNUMBER(SEARCH("ESPERANDO",L4)),ISNUMBER(SEARCH("ESPERANDO",F4))),"Sin respuesta / Inactivo",IF(OR(ISNUMBER(SEARCH("PENDIENTE",L4)),ISNUMBER(SEARCH("PENDIENTE",F4)),ISNUMBER(SEARCH("COMPROMISO",F4)),ISNUMBER(SEARCH("COMPROMISO",L4)),ISNUMBER(SEARCH("PROCESO",F4)),ISNUMBER(SEARCH("LLAMAR",F4)),ISNUMBER(SEARCH("ABONO",J4)),EXACT(L4,"P"),EXACT(F4,"P")),"Pendiente / Compromiso","Sin gestionar")))) -> Al día | P4: =IF(B4="","",IF(E4="","Sin definir",IF(ISNUMBER(SEARCH("ITIL",E4)),"ITIL",IF(ISNUMBER(SEARCH("ISO 27001",E4)),"ISO 27001",IF(ISNUMBER(SEARCH("ISO 42001",E4)),"ISO 42001",IF(ISNUMBER(SEARCH("ISO",E4)),"Otras ISO",IF(ISNUMBER(SEARCH("SCRUM",E4)),"SCRUM",IF(ISNUMBER(SEARCH("BRIDGE",E4)),"BRIDGE",IF(ISNUMBER(SEARCH("CDS",E4)),"CDS",IF(ISNUMBER(SEARCH("TOGAF",E4)),"TOGAF",IF(ISNUMBER(SEARCH("DPI",E4)),"DPI",IF(ISNUMBER(SEARCH("DITS",E4)),"DITS",IF(ISNUMBER(SEARCH("AGILE",E4)),"AGILE",IF(ISNUMBER(SEARCH("Ciberseguridad",E4)),"Ciberseguridad","Otros")))))))))))))) -> ITIL | Q4: =IF(B4="","",IF(ISNUMBER(K4),IF(K4<=3,"1-3 meses",IF(K4<=6,"4-6 meses","+6 meses")),"Sin dato registrado")) -> 4-6 meses | R4: =IF(OR(B4="",M4=""),"",RANK(M4,$M$3:$M$306)+COUNTIF($M$3:M4,M4)-1) -> 60
A5: 4 | B5: José León Nuñez Oñate | C5: 46108 | D5: Ximena | E5: ITIL 4 Fundamentos | F5: Curso y examen | G5: PROCESO | H5: 100000 | I5: 850000 | K5: 6 | M5: =IF(B5="","",IF(ISNUMBER(I5),I5,IFERROR(VALUE(SUBSTITUTE(SUBSTITUTE(I5,"$",""),".","")),0))) -> 850000 | N5: =IF(B5="","",PROPER(TRIM(D5))) -> Ximena | O5: =IF(B5="","",IF(OR(ISNUMBER(SEARCH("AL DIA",L5)),ISNUMBER(SEARCH("AL DIA",F5))),"Al día",IF(OR(ISNUMBER(SEARCH("QUIETO",L5)),ISNUMBER(SEARCH("QUIETO",F5)),ISNUMBER(SEARCH("ESPERANDO",L5)),ISNUMBER(SEARCH("ESPERANDO",F5))),"Sin respuesta / Inactivo",IF(OR(ISNUMBER(SEARCH("PENDIENTE",L5)),ISNUMBER(SEARCH("PENDIENTE",F5)),ISNUMBER(SEARCH("COMPROMISO",F5)),ISNUMBER(SEARCH("COMPROMISO",L5)),ISNUMBER(SEARCH("PROCESO",F5)),ISNUMBER(SEARCH("LLAMAR",F5)),ISNUMBER(SEARCH("ABONO",J5)),EXACT(L5,"P"),EXACT(F5,"P")),"Pendiente / Compromiso","Sin gestionar")))) -> Sin gestionar | P5: =IF(B5="","",IF(E5="","Sin definir",IF(ISNUMBER(SEARCH("ITIL",E5)),"ITIL",IF(ISNUMBER(SEARCH("ISO 27001",E5)),"ISO 27001",IF(ISNUMBER(SEARCH("ISO 42001",E5)),"ISO 42001",IF(ISNUMBER(SEARCH("ISO",E5)),"Otras ISO",IF(ISNUMBER(SEARCH("SCRUM",E5)),"SCRUM",IF(ISNUMBER(SEARCH("BRIDGE",E5)),"BRIDGE",IF(ISNUMBER(SEARCH("CDS",E5)),"CDS",IF(ISNUMBER(SEARCH("TOGAF",E5)),"TOGAF",IF(ISNUMBER(SEARCH("DPI",E5)),"DPI",IF(ISNUMBER(SEARCH("DITS",E5)),"DITS",IF(ISNUMBER(SEARCH("AGILE",E5)),"AGILE",IF(ISNUMBER(SEARCH("Ciberseguridad",E5)),"Ciberseguridad","Otros")))))))))))))) -> ITIL | Q5: =IF(B5="","",IF(ISNUMBER(K5),IF(K5<=3,"1-3 meses",IF(K5<=6,"4-6 meses","+6 meses")),"Sin dato registrado")) -> 4-6 meses | R5: =IF(OR(B5="",M5=""),"",RANK(M5,$M$3:$M$306)+COUNTIF($M$3:M5,M5)-1) -> 27
A6: 5 | B6: Luis Alberto Solarte Lopez | C6: 46108 | D6: Ximena | E6: ITIL 4 Fundamentos | F6: Curso y examen | G6: PROCESO | H6: 100000 | I6: 1267000 | K6: 6 | M6: =IF(B6="","",IF(ISNUMBER(I6),I6,IFERROR(VALUE(SUBSTITUTE(SUBSTITUTE(I6,"$",""),".","")),0))) -> 1267000 | N6: =IF(B6="","",PROPER(TRIM(D6))) -> Ximena | O6: =IF(B6="","",IF(OR(ISNUMBER(SEARCH("AL DIA",L6)),ISNUMBER(SEARCH("AL DIA",F6))),"Al día",IF(OR(ISNUMBER(SEARCH("QUIETO",L6)),ISNUMBER(SEARCH("QUIETO",F6)),ISNUMBER(SEARCH("ESPERANDO",L6)),ISNUMBER(SEARCH("ESPERANDO",F6))),"Sin respuesta / Inactivo",IF(OR(ISNUMBER(SEARCH("PENDIENTE",L6)),ISNUMBER(SEARCH("PENDIENTE",F6)),ISNUMBER(SEARCH("COMPROMISO",F6)),ISNUMBER(SEARCH("COMPROMISO",L6)),ISNUMBER(SEARCH("PROCESO",F6)),ISNUMBER(SEARCH("LLAMAR",F6)),ISNUMBER(SEARCH("ABONO",J6)),EXACT(L6,"P"),EXACT(F6,"P")),"Pendiente / Compromiso","Sin gestionar")))) -> Sin gestionar | P6: =IF(B6="","",IF(E6="","Sin definir",IF(ISNUMBER(SEARCH("ITIL",E6)),"ITIL",IF(ISNUMBER(SEARCH("ISO 27001",E6)),"ISO 27001",IF(ISNUMBER(SEARCH("ISO 42001",E6)),"ISO 42001",IF(ISNUMBER(SEARCH("ISO",E6)),"Otras ISO",IF(ISNUMBER(SEARCH("SCRUM",E6)),"SCRUM",IF(ISNUMBER(SEARCH("BRIDGE",E6)),"BRIDGE",IF(ISNUMBER(SEARCH("CDS",E6)),"CDS",IF(ISNUMBER(SEARCH("TOGAF",E6)),"TOGAF",IF(ISNUMBER(SEARCH("DPI",E6)),"DPI",IF(ISNUMBER(SEARCH("DITS",E6)),"DITS",IF(ISNUMBER(SEARCH("AGILE",E6)),"AGILE",IF(ISNUMBER(SEARCH("Ciberseguridad",E6)),"Ciberseguridad","Otros")))))))))))))) -> ITIL | Q6: =IF(B6="","",IF(ISNUMBER(K6),IF(K6<=3,"1-3 meses",IF(K6<=6,"4-6 meses","+6 meses")),"Sin dato registrado")) -> 4-6 meses | R6: =IF(OR(B6="",M6=""),"",RANK(M6,$M$3:$M$306)+COUNTIF($M$3:M6,M6)-1) -> 14
A7: 6 | B7: Juan Pablo Zambrano Sanchez | C7: 46108 | D7: Ximena | E7: ISO 22301 | F7: Curso y examen | G7: PROCESO | H7: 110000 | I7: 1200000 | K7: 5 | M7: =IF(B7="","",IF(ISNUMBER(I7),I7,IFERROR(VALUE(SUBSTITUTE(SUBSTITUTE(I7,"$",""),".","")),0))) -> 1200000 | N7: =IF(B7="","",PROPER(TRIM(D7))) -> Ximena | O7: =IF(B7="","",IF(OR(ISNUMBER(SEARCH("AL DIA",L7)),ISNUMBER(SEARCH("AL DIA",F7))),"Al día",IF(OR(ISNUMBER(SEARCH("QUIETO",L7)),ISNUMBER(SEARCH("QUIETO",F7)),ISNUMBER(SEARCH("ESPERANDO",L7)),ISNUMBER(SEARCH("ESPERANDO",F7))),"Sin respuesta / Inactivo",IF(OR(ISNUMBER(SEARCH("PENDIENTE",L7)),ISNUMBER(SEARCH("PENDIENTE",F7)),ISNUMBER(SEARCH("COMPROMISO",F7)),ISNUMBER(SEARCH("COMPROMISO",L7)),ISNUMBER(SEARCH("PROCESO",F7)),ISNUMBER(SEARCH("LLAMAR",F7)),ISNUMBER(SEARCH("ABONO",J7)),EXACT(L7,"P"),EXACT(F7,"P")),"Pendiente / Compromiso","Sin gestionar")))) -> Sin gestionar | P7: =IF(B7="","",IF(E7="","Sin definir",IF(ISNUMBER(SEARCH("ITIL",E7)),"ITIL",IF(ISNUMBER(SEARCH("ISO 27001",E7)),"ISO 27001",IF(ISNUMBER(SEARCH("ISO 42001",E7)),"ISO 42001",IF(ISNUMBER(SEARCH("ISO",E7)),"Otras ISO",IF(ISNUMBER(SEARCH("SCRUM",E7)),"SCRUM",IF(ISNUMBER(SEARCH("BRIDGE",E7)),"BRIDGE",IF(ISNUMBER(SEARCH("CDS",E7)),"CDS",IF(ISNUMBER(SEARCH("TOGAF",E7)),"TOGAF",IF(ISNUMBER(SEARCH("DPI",E7)),"DPI",IF(ISNUMBER(SEARCH("DITS",E7)),"DITS",IF(ISNUMBER(SEARCH("AGILE",E7)),"AGILE",IF(ISNUMBER(SEARCH("Ciberseguridad",E7)),"Ciberseguridad","Otros")))))))))))))) -> Otras ISO | Q7: =IF(B7="","",IF(ISNUMBER(K7),IF(K7<=3,"1-3 meses",IF(K7<=6,"4-6 meses","+6 meses")),"Sin dato registrado")) -> 4-6 meses | R7: =IF(OR(B7="",M7=""),"",RANK(M7,$M$3:$M$306)+COUNTIF($M$3:M7,M7)-1) -> 15
A8: 7 | B8: Dorian Lizeth Vera Cano | C8: 46108 | D8: Ximena | G8: CAMBIO AGILE A ITIL | M8: =IF(B8="","",IF(ISNUMBER(I8),I8,IFERROR(VALUE(SUBSTITUTE(SUBSTITUTE(I8,"$",""),".","")),0))) -> 0 | N8: =IF(B8="","",PROPER(TRIM(D8))) -> Ximena | O8: =IF(B8="","",IF(OR(ISNUMBER(SEARCH("AL DIA",L8)),ISNUMBER(SEARCH("AL DIA",F8))),"Al día",IF(OR(ISNUMBER(SEARCH("QUIETO",L8)),ISNUMBER(SEARCH("QUIETO",F8)),ISNUMBER(SEARCH("ESPERANDO",L8)),ISNUMBER(SEARCH("ESPERANDO",F8))),"Sin respuesta / Inactivo",IF(OR(ISNUMBER(SEARCH("PENDIENTE",L8)),ISNUMBER(SEARCH("PENDIENTE",F8)),ISNUMBER(SEARCH("COMPROMISO",F8)),ISNUMBER(SEARCH("COMPROMISO",L8)),ISNUMBER(SEARCH("PROCESO",F8)),ISNUMBER(SEARCH("LLAMAR",F8)),ISNUMBER(SEARCH("ABONO",J8)),EXACT(L8,"P"),EXACT(F8,"P")),"Pendiente / Compromiso","Sin gestionar")))) -> Sin gestionar | P8: =IF(B8="","",IF(E8="","Sin definir",IF(ISNUMBER(SEARCH("ITIL",E8)),"ITIL",IF(ISNUMBER(SEARCH("ISO 27001",E8)),"ISO 27001",IF(ISNUMBER(SEARCH("ISO 42001",E8)),"ISO 42001",IF(ISNUMBER(SEARCH("ISO",E8)),"Otras ISO",IF(ISNUMBER(SEARCH("SCRUM",E8)),"SCRUM",IF(ISNUMBER(SEARCH("BRIDGE",E8)),"BRIDGE",IF(ISNUMBER(SEARCH("CDS",E8)),"CDS",IF(ISNUMBER(SEARCH("TOGAF",E8)),"TOGAF",IF(ISNUMBER(SEARCH("DPI",E8)),"DPI",IF(ISNUMBER(SEARCH("DITS",E8)),"DITS",IF(ISNUMBER(SEARCH("AGILE",E8)),"AGILE",IF(ISNUMBER(SEARCH("Ciberseguridad",E8)),"Ciberseguridad","Otros")))))))))))))) -> Sin definir | Q8: =IF(B8="","",IF(ISNUMBER(K8),IF(K8<=3,"1-3 meses",IF(K8<=6,"4-6 meses","+6 meses")),"Sin dato registrado")) -> Sin dato registrado | R8: =IF(OR(B8="",M8=""),"",RANK(M8,$M$3:$M$306)+COUNTIF($M$3:M8,M8)-1) -> 61
A9: 8 | B9: Vivian Sanz Martelo | G9: COMPROMISO DE PAGO | H9: X | I9: $1.000.000 | J9: ABONO 10ABRIL | K9: X | L9: PAGO AL DIA | M9: =IF(B9="","",IF(ISNUMBER(I9),I9,IFERROR(VALUE(SUBSTITUTE(SUBSTITUTE(I9,"$",""),".","")),0))) -> 1000000 | N9: =IF(B9="","",PROPER(TRIM(D9))) | O9: =IF(B9="","",IF(OR(ISNUMBER(SEARCH("AL DIA",L9)),ISNUMBER(SEARCH("AL DIA",F9))),"Al día",IF(OR(ISNUMBER(SEARCH("QUIETO",L9)),ISNUMBER(SEARCH("QUIETO",F9)),ISNUMBER(SEARCH("ESPERANDO",L9)),ISNUMBER(SEARCH("ESPERANDO",F9))),"Sin respuesta / Inactivo",IF(OR(ISNUMBER(SEARCH("PENDIENTE",L9)),ISNUMBER(SEARCH("PENDIENTE",F9)),ISNUMBER(SEARCH("COMPROMISO",F9)),ISNUMBER(SEARCH("COMPROMISO",L9)),ISNUMBER(SEARCH("PROCESO",F9)),ISNUMBER(SEARCH("LLAMAR",F9)),ISNUMBER(SEARCH("ABONO",J9)),EXACT(L9,"P"),EXACT(F9,"P")),"Pendiente / Compromiso","Sin gestionar")))) -> Al día | P9: =IF(B9="","",IF(E9="","Sin definir",IF(ISNUMBER(SEARCH("ITIL",E9)),"ITIL",IF(ISNUMBER(SEARCH("ISO 27001",E9)),"ISO 27001",IF(ISNUMBER(SEARCH("ISO 42001",E9)),"ISO 42001",IF(ISNUMBER(SEARCH("ISO",E9)),"Otras ISO",IF(ISNUMBER(SEARCH("SCRUM",E9)),"SCRUM",IF(ISNUMBER(SEARCH("BRIDGE",E9)),"BRIDGE",IF(ISNUMBER(SEARCH("CDS",E9)),"CDS",IF(ISNUMBER(SEARCH("TOGAF",E9)),"TOGAF",IF(ISNUMBER(SEARCH("DPI",E9)),"DPI",IF(ISNUMBER(SEARCH("DITS",E9)),"DITS",IF(ISNUMBER(SEARCH("AGILE",E9)),"AGILE",IF(ISNUMBER(SEARCH("Ciberseguridad",E9)),"Ciberseguridad","Otros")))))))))))))) -> Sin definir | Q9: =IF(B9="","",IF(ISNUMBER(K9),IF(K9<=3,"1-3 meses",IF(K9<=6,"4-6 meses","+6 meses")),"Sin dato registrado")) -> Sin dato registrado | R9: =IF(OR(B9="",M9=""),"",RANK(M9,$M$3:$M$306)+COUNTIF($M$3:M9,M9)-1) -> 18
A10: 9 | B10: Sindy Lorena Ortiz Gonzalez | D10: Sebas | E10: SCRUM gold | G10: COMPROMISO DE PAGO | H10: X | I10: $1.100.000 | J10: ABONO 15 JUN | L10: Pendiente X FECHA | M10: =IF(B10="","",IF(ISNUMBER(I10),I10,IFERROR(VALUE(SUBSTITUTE(SUBSTITUTE(I10,"$",""),".","")),0))) -> 1100000 | N10: =IF(B10="","",PROPER(TRIM(D10))) -> Sebas | O10: =IF(B10="","",IF(OR(ISNUMBER(SEARCH("AL DIA",L10)),ISNUMBER(SEARCH("AL DIA",F10))),"Al día",IF(OR(ISNUMBER(SEARCH("QUIETO",L10)),ISNUMBER(SEARCH("QUIETO",F10)),ISNUMBER(SEARCH("ESPERANDO",L10)),ISNUMBER(SEARCH("ESPERANDO",F10))),"Sin respuesta / Inactivo",IF(OR(ISNUMBER(SEARCH("PENDIENTE",L10)),ISNUMBER(SEARCH("PENDIENTE",F10)),ISNUMBER(SEARCH("COMPROMISO",F10)),ISNUMBER(SEARCH("COMPROMISO",L10)),ISNUMBER(SEARCH("PROCESO",F10)),ISNUMBER(SEARCH("LLAMAR",F10)),ISNUMBER(SEARCH("ABONO",J10)),EXACT(L10,"P"),EXACT(F10,"P")),"Pendiente / Compromiso","Sin gestionar")))) -> Pendiente / Compromiso | P10: =IF(B10="","",IF(E10="","Sin definir",IF(ISNUMBER(SEARCH("ITIL",E10)),"ITIL",IF(ISNUMBER(SEARCH("ISO 27001",E10)),"ISO 27001",IF(ISNUMBER(SEARCH("ISO 42001",E10)),"ISO 42001",IF(ISNUMBER(SEARCH("ISO",E10)),"Otras ISO",IF(ISNUMBER(SEARCH("SCRUM",E10)),"SCRUM",IF(ISNUMBER(SEARCH("BRIDGE",E10)),"BRIDGE",IF(ISNUMBER(SEARCH("CDS",E10)),"CDS",IF(ISNUMBER(SEARCH("TOGAF",E10)),"TOGAF",IF(ISNUMBER(SEARCH("DPI",E10)),"DPI",IF(ISNUMBER(SEARCH("DITS",E10)),"DITS",IF(ISNUMBER(SEARCH("AGILE",E10)),"AGILE",IF(ISNUMBER(SEARCH("Ciberseguridad",E10)),"Ciberseguridad","Otros")))))))))))))) -> SCRUM | Q10: =IF(B10="","",IF(ISNUMBER(K10),IF(K10<=3,"1-3 meses",IF(K10<=6,"4-6 meses","+6 meses")),"Sin dato registrado")) -> Sin dato registrado | R10: =IF(OR(B10="",M10=""),"",RANK(M10,$M$3:$M$306)+COUNTIF($M$3:M10,M10)-1) -> 17
A11: 10 | B11: Osiris Yasbleidy Torres Gutierrez | D11: Sebas | E11: Ciberseguridad | G11: COMPROMISO DE PAGO | H11: X | I11: 850000 | J11: ABONO 15 ABR | L11: PAGO AL DIA | M11: =IF(B11="","",IF(ISNUMBER(I11),I11,IFERROR(VALUE(SUBSTITUTE(SUBSTITUTE(I11,"$",""),".","")),0))) -> 850000 | N11: =IF(B11="","",PROPER(TRIM(D11))) -> Sebas | O11: =IF(B11="","",IF(OR(ISNUMBER(SEARCH("AL DIA",L11)),ISNUMBER(SEARCH("AL DIA",F11))),"Al día",IF(OR(ISNUMBER(SEARCH("QUIETO",L11)),ISNUMBER(SEARCH("QUIETO",F11)),ISNUMBER(SEARCH("ESPERANDO",L11)),ISNUMBER(SEARCH("ESPERANDO",F11))),"Sin respuesta / Inactivo",IF(OR(ISNUMBER(SEARCH("PENDIENTE",L11)),ISNUMBER(SEARCH("PENDIENTE",F11)),ISNUMBER(SEARCH("COMPROMISO",F11)),ISNUMBER(SEARCH("COMPROMISO",L11)),ISNUMBER(SEARCH("PROCESO",F11)),ISNUMBER(SEARCH("LLAMAR",F11)),ISNUMBER(SEARCH("ABONO",J11)),EXACT(L11,"P"),EXACT(F11,"P")),"Pendiente / Compromiso","Sin gestionar")))) -> Al día | P11: =IF(B11="","",IF(E11="","Sin definir",IF(ISNUMBER(SEARCH("ITIL",E11)),"ITIL",IF(ISNUMBER(SEARCH("ISO 27001",E11)),"ISO 27001",IF(ISNUMBER(SEARCH("ISO 42001",E11)),"ISO 42001",IF(ISNUMBER(SEARCH("ISO",E11)),"Otras ISO",IF(ISNUMBER(SEARCH("SCRUM",E11)),"SCRUM",IF(ISNUMBER(SEARCH("BRIDGE",E11)),"BRIDGE",IF(ISNUMBER(SEARCH("CDS",E11)),"CDS",IF(ISNUMBER(SEARCH("TOGAF",E11)),"TOGAF",IF(ISNUMBER(SEARCH("DPI",E11)),"DPI",IF(ISNUMBER(SEARCH("DITS",E11)),"DITS",IF(ISNUMBER(SEARCH("AGILE",E11)),"AGILE",IF(ISNUMBER(SEARCH("Ciberseguridad",E11)),"Ciberseguridad","Otros")))))))))))))) -> Ciberseguridad | Q11: =IF(B11="","",IF(ISNUMBER(K11),IF(K11<=3,"1-3 meses",IF(K11<=6,"4-6 meses","+6 meses")),"Sin dato registrado")) -> Sin dato registrado | R11: =IF(OR(B11="",M11=""),"",RANK(M11,$M$3:$M$306)+COUNTIF($M$3:M11,M11)-1) -> 28
A12: 11 | B12: Gianella Mendoza Ruiz | D12: Sebas | E12: ITIL 4 Fundamentos | G12: COMPROMISO DE PAGO | H12: X | I12: 975000 | J12: ABONO 30 ABR | L12: PAGO AL DIA | M12: =IF(B12="","",IF(ISNUMBER(I12),I12,IFERROR(VALUE(SUBSTITUTE(SUBSTITUTE(I12,"$",""),".","")),0))) -> 975000 | N12: =IF(B12="","",PROPER(TRIM(D12))) -> Sebas | O12: =IF(B12="","",IF(OR(ISNUMBER(SEARCH("AL DIA",L12)),ISNUMBER(SEARCH("AL DIA",F12))),"Al día",IF(OR(ISNUMBER(SEARCH("QUIETO",L12)),ISNUMBER(SEARCH("QUIETO",F12)),ISNUMBER(SEARCH("ESPERANDO",L12)),ISNUMBER(SEARCH("ESPERANDO",F12))),"Sin respuesta / Inactivo",IF(OR(ISNUMBER(SEARCH("PENDIENTE",L12)),ISNUMBER(SEARCH("PENDIENTE",F12)),ISNUMBER(SEARCH("COMPROMISO",F12)),ISNUMBER(SEARCH("COMPROMISO",L12)),ISNUMBER(SEARCH("PROCESO",F12)),ISNUMBER(SEARCH("LLAMAR",F12)),ISNUMBER(SEARCH("ABONO",J12)),EXACT(L12,"P"),EXACT(F12,"P")),"Pendiente / Compromiso","Sin gestionar")))) -> Al día | P12: =IF(B12="","",IF(E12="","Sin definir",IF(ISNUMBER(SEARCH("ITIL",E12)),"ITIL",IF(ISNUMBER(SEARCH("ISO 27001",E12)),"ISO 27001",IF(ISNUMBER(SEARCH("ISO 42001",E12)),"ISO 42001",IF(ISNUMBER(SEARCH("ISO",E12)),"Otras ISO",IF(ISNUMBER(SEARCH("SCRUM",E12)),"SCRUM",IF(ISNUMBER(SEARCH("BRIDGE",E12)),"BRIDGE",IF(ISNUMBER(SEARCH("CDS",E12)),"CDS",IF(ISNUMBER(SEARCH("TOGAF",E12)),"TOGAF",IF(ISNUMBER(SEARCH("DPI",E12)),"DPI",IF(ISNUMBER(SEARCH("DITS",E12)),"DITS",IF(ISNUMBER(SEARCH("AGILE",E12)),"AGILE",IF(ISNUMBER(SEARCH("Ciberseguridad",E12)),"Ciberseguridad","Otros")))))))))))))) -> ITIL | Q12: =IF(B12="","",IF(ISNUMBER(K12),IF(K12<=3,"1-3 meses",IF(K12<=6,"4-6 meses","+6 meses")),"Sin dato registrado")) -> Sin dato registrado | R12: =IF(OR(B12="",M12=""),"",RANK(M12,$M$3:$M$306)+COUNTIF($M$3:M12,M12)-1) -> 22
A13: 12 | B13: Luis Fernando Ramirez Cancelado | D13: Ximena | E13: Ciberseguridad | G13: COMPROMISO DE PAGO | H13: X | I13: 500000 | J13: ABONO 16 ABR | L13: Pendiente X FECHA | M13: =IF(B13="","",IF(ISNUMBER(I13),I13,IFERROR(VALUE(SUBSTITUTE(SUBSTITUTE(I13,"$",""),".","")),0))) -> 500000 | N13: =IF(B13="","",PROPER(TRIM(D13))) -> Ximena | O13: =IF(B13="","",IF(OR(ISNUMBER(SEARCH("AL DIA",L13)),ISNUMBER(SEARCH("AL DIA",F13))),"Al día",IF(OR(ISNUMBER(SEARCH("QUIETO",L13)),ISNUMBER(SEARCH("QUIETO",F13)),ISNUMBER(SEARCH("ESPERANDO",L13)),ISNUMBER(SEARCH("ESPERANDO",F13))),"Sin respuesta / Inactivo",IF(OR(ISNUMBER(SEARCH("PENDIENTE",L13)),ISNUMBER(SEARCH("PENDIENTE",F13)),ISNUMBER(SEARCH("COMPROMISO",F13)),ISNUMBER(SEARCH("COMPROMISO",L13)),ISNUMBER(SEARCH("PROCESO",F13)),ISNUMBER(SEARCH("LLAMAR",F13)),ISNUMBER(SEARCH("ABONO",J13)),EXACT(L13,"P"),EXACT(F13,"P")),"Pendiente / Compromiso","Sin gestionar")))) -> Pendiente / Compromiso | P13: =IF(B13="","",IF(E13="","Sin definir",IF(ISNUMBER(SEARCH("ITIL",E13)),"ITIL",IF(ISNUMBER(SEARCH("ISO 27001",E13)),"ISO 27001",IF(ISNUMBER(SEARCH("ISO 42001",E13)),"ISO 42001",IF(ISNUMBER(SEARCH("ISO",E13)),"Otras ISO",IF(ISNUMBER(SEARCH("SCRUM",E13)),"SCRUM",IF(ISNUMBER(SEARCH("BRIDGE",E13)),"BRIDGE",IF(ISNUMBER(SEARCH("CDS",E13)),"CDS",IF(ISNUMBER(SEARCH("TOGAF",E13)),"TOGAF",IF(ISNUMBER(SEARCH("DPI",E13)),"DPI",IF(ISNUMBER(SEARCH("DITS",E13)),"DITS",IF(ISNUMBER(SEARCH("AGILE",E13)),"AGILE",IF(ISNUMBER(SEARCH("Ciberseguridad",E13)),"Ciberseguridad","Otros")))))))))))))) -> Ciberseguridad | Q13: =IF(B13="","",IF(ISNUMBER(K13),IF(K13<=3,"1-3 meses",IF(K13<=6,"4-6 meses","+6 meses")),"Sin dato registrado")) -> Sin dato registrado | R13: =IF(OR(B13="",M13=""),"",RANK(M13,$M$3:$M$306)+COUNTIF($M$3:M13,M13)-1) -> 46
A14: 14 | B14: Meredith Ibarra Uyaban | D14: Ximena | E14: ISO 27001 | G14: COMPROMISO DE PAGO | H14: X | I14: 640000 | J14: ABONO 30ABR/31MAY/30JUN | L14: Pendiente X FECHA | M14: =IF(B14="","",IF(ISNUMBER(I14),I14,IFERROR(VALUE(SUBSTITUTE(SUBSTITUTE(I14,"$",""),".","")),0))) -> 640000 | N14: =IF(B14="","",PROPER(TRIM(D14))) -> Ximena | O14: =IF(B14="","",IF(OR(ISNUMBER(SEARCH("AL DIA",L14)),ISNUMBER(SEARCH("AL DIA",F14))),"Al día",IF(OR(ISNUMBER(SEARCH("QUIETO",L14)),ISNUMBER(SEARCH("QUIETO",F14)),ISNUMBER(SEARCH("ESPERANDO",L14)),ISNUMBER(SEARCH("ESPERANDO",F14))),"Sin respuesta / Inactivo",IF(OR(ISNUMBER(SEARCH("PENDIENTE",L14)),ISNUMBER(SEARCH("PENDIENTE",F14)),ISNUMBER(SEARCH("COMPROMISO",F14)),ISNUMBER(SEARCH("COMPROMISO",L14)),ISNUMBER(SEARCH("PROCESO",F14)),ISNUMBER(SEARCH("LLAMAR",F14)),ISNUMBER(SEARCH("ABONO",J14)),EXACT(L14,"P"),EXACT(F14,"P")),"Pendiente / Compromiso","Sin gestionar")))) -> Pendiente / Compromiso | P14: =IF(B14="","",IF(E14="","Sin definir",IF(ISNUMBER(SEARCH("ITIL",E14)),"ITIL",IF(ISNUMBER(SEARCH("ISO 27001",E14)),"ISO 27001",IF(ISNUMBER(SEARCH("ISO 42001",E14)),"ISO 42001",IF(ISNUMBER(SEARCH("ISO",E14)),"Otras ISO",IF(ISNUMBER(SEARCH("SCRUM",E14)),"SCRUM",IF(ISNUMBER(SEARCH("BRIDGE",E14)),"BRIDGE",IF(ISNUMBER(SEARCH("CDS",E14)),"CDS",IF(ISNUMBER(SEARCH("TOGAF",E14)),"TOGAF",IF(ISNUMBER(SEARCH("DPI",E14)),"DPI",IF(ISNUMBER(SEARCH("DITS",E14)),"DITS",IF(ISNUMBER(SEARCH("AGILE",E14)),"AGILE",IF(ISNUMBER(SEARCH("Ciberseguridad",E14)),"Ciberseguridad","Otros")))))))))))))) -> ISO 27001 | Q14: =IF(B14="","",IF(ISNUMBER(K14),IF(K14<=3,"1-3 meses",IF(K14<=6,"4-6 meses","+6 meses")),"Sin dato registrado")) -> Sin dato registrado | R14: =IF(OR(B14="",M14=""),"",RANK(M14,$M$3:$M$306)+COUNTIF($M$3:M14,M14)-1) -> 43
A15: 15 | B15: Maria Paula villamil | D15: Ximena | E15: ISO 27001 | G15: COMPROMISO DE PAGO | H15: X | I15: 594967 | J15: ABONO 30ABR/31MAY/30JUN | L15: Pendiente X FECHA | M15: =IF(B15="","",IF(ISNUMBER(I15),I15,IFERROR(VALUE(SUBSTITUTE(SUBSTITUTE(I15,"$",""),".","")),0))) -> 594967 | N15: =IF(B15="","",PROPER(TRIM(D15))) -> Ximena | O15: =IF(B15="","",IF(OR(ISNUMBER(SEARCH("AL DIA",L15)),ISNUMBER(SEARCH("AL DIA",F15))),"Al día",IF(OR(ISNUMBER(SEARCH("QUIETO",L15)),ISNUMBER(SEARCH("QUIETO",F15)),ISNUMBER(SEARCH("ESPERANDO",L15)),ISNUMBER(SEARCH("ESPERANDO",F15))),"Sin respuesta / Inactivo",IF(OR(ISNUMBER(SEARCH("PENDIENTE",L15)),ISNUMBER(SEARCH("PENDIENTE",F15)),ISNUMBER(SEARCH("COMPROMISO",F15)),ISNUMBER(SEARCH("COMPROMISO",L15)),ISNUMBER(SEARCH("PROCESO",F15)),ISNUMBER(SEARCH("LLAMAR",F15)),ISNUMBER(SEARCH("ABONO",J15)),EXACT(L15,"P"),EXACT(F15,"P")),"Pendiente / Compromiso","Sin gestionar")))) -> Pendiente / Compromiso | P15: =IF(B15="","",IF(E15="","Sin definir",IF(ISNUMBER(SEARCH("ITIL",E15)),"ITIL",IF(ISNUMBER(SEARCH("ISO 27001",E15)),"ISO 27001",IF(ISNUMBER(SEARCH("ISO 42001",E15)),"ISO 42001",IF(ISNUMBER(SEARCH("ISO",E15)),"Otras ISO",IF(ISNUMBER(SEARCH("SCRUM",E15)),"SCRUM",IF(ISNUMBER(SEARCH("BRIDGE",E15)),"BRIDGE",IF(ISNUMBER(SEARCH("CDS",E15)),"CDS",IF(ISNUMBER(SEARCH("TOGAF",E15)),"TOGAF",IF(ISNUMBER(SEARCH("DPI",E15)),"DPI",IF(ISNUMBER(SEARCH("DITS",E15)),"DITS",IF(ISNUMBER(SEARCH("AGILE",E15)),"AGILE",IF(ISNUMBER(SEARCH("Ciberseguridad",E15)),"Ciberseguridad","Otros")))))))))))))) -> ISO 27001 | Q15: =IF(B15="","",IF(ISNUMBER(K15),IF(K15<=3,"1-3 meses",IF(K15<=6,"4-6 meses","+6 meses")),"Sin dato registrado")) -> Sin dato registrado | R15: =IF(OR(B15="",M15=""),"",RANK(M15,$M$3:$M$306)+COUNTIF($M$3:M15,M15)-1) -> 45
A16: 16 | B16: Nilson Andres Urresti Gonzalez | D16: Carolina | E16: ITIL 4 Fundamentos | G16: COMPROMISO DE PAGO | H16: X | I16: 925000 | M16: =IF(B16="","",IF(ISNUMBER(I16),I16,IFERROR(VALUE(SUBSTITUTE(SUBSTITUTE(I16,"$",""),".","")),0))) -> 925000 | N16: =IF(B16="","",PROPER(TRIM(D16))) -> Carolina | O16: =IF(B16="","",IF(OR(ISNUMBER(SEARCH("AL DIA",L16)),ISNUMBER(SEARCH("AL DIA",F16))),"Al día",IF(OR(ISNUMBER(SEARCH("QUIETO",L16)),ISNUMBER(SEARCH("QUIETO",F16)),ISNUMBER(SEARCH("ESPERANDO",L16)),ISNUMBER(SEARCH("ESPERANDO",F16))),"Sin respuesta / Inactivo",IF(OR(ISNUMBER(SEARCH("PENDIENTE",L16)),ISNUMBER(SEARCH("PENDIENTE",F16)),ISNUMBER(SEARCH("COMPROMISO",F16)),ISNUMBER(SEARCH("COMPROMISO",L16)),ISNUMBER(SEARCH("PROCESO",F16)),ISNUMBER(SEARCH("LLAMAR",F16)),ISNUMBER(SEARCH("ABONO",J16)),EXACT(L16,"P"),EXACT(F16,"P")),"Pendiente / Compromiso","Sin gestionar")))) -> Sin gestionar | P16: =IF(B16="","",IF(E16="","Sin definir",IF(ISNUMBER(SEARCH("ITIL",E16)),"ITIL",IF(ISNUMBER(SEARCH("ISO 27001",E16)),"ISO 27001",IF(ISNUMBER(SEARCH("ISO 42001",E16)),"ISO 42001",IF(ISNUMBER(SEARCH("ISO",E16)),"Otras ISO",IF(ISNUMBER(SEARCH("SCRUM",E16)),"SCRUM",IF(ISNUMBER(SEARCH("BRIDGE",E16)),"BRIDGE",IF(ISNUMBER(SEARCH("CDS",E16)),"CDS",IF(ISNUMBER(SEARCH("TOGAF",E16)),"TOGAF",IF(ISNUMBER(SEARCH("DPI",E16)),"DPI",IF(ISNUMBER(SEARCH("DITS",E16)),"DITS",IF(ISNUMBER(SEARCH("AGILE",E16)),"AGILE",IF(ISNUMBER(SEARCH("Ciberseguridad",E16)),"Ciberseguridad","Otros")))))))))))))) -> ITIL | Q16: =IF(B16="","",IF(ISNUMBER(K16),IF(K16<=3,"1-3 meses",IF(K16<=6,"4-6 meses","+6 meses")),"Sin dato registrado")) -> Sin dato registrado | R16: =IF(OR(B16="",M16=""),"",RANK(M16,$M$3:$M$306)+COUNTIF($M$3:M16,M16)-1) -> 24
A17: 17 | B17: Gelmer Parada Parada | D17: Sebas | E17: ITIL 4 Fundamentos | G17: llamar | H17: - | I17: 1450000 | J17: - | K17: - | L17: - | M17: =IF(B17="","",IF(ISNUMBER(I17),I17,IFERROR(VALUE(SUBSTITUTE(SUBSTITUTE(I17,"$",""),".","")),0))) -> 1450000 | N17: =IF(B17="","",PROPER(TRIM(D17))) -> Sebas | O17: =IF(B17="","",IF(OR(ISNUMBER(SEARCH("AL DIA",L17)),ISNUMBER(SEARCH("AL DIA",F17))),"Al día",IF(OR(ISNUMBER(SEARCH("QUIETO",L17)),ISNUMBER(SEARCH("QUIETO",F17)),ISNUMBER(SEARCH("ESPERANDO",L17)),ISNUMBER(SEARCH("ESPERANDO",F17))),"Sin respuesta / Inactivo",IF(OR(ISNUMBER(SEARCH("PENDIENTE",L17)),ISNUMBER(SEARCH("PENDIENTE",F17)),ISNUMBER(SEARCH("COMPROMISO",F17)),ISNUMBER(SEARCH("COMPROMISO",L17)),ISNUMBER(SEARCH("PROCESO",F17)),ISNUMBER(SEARCH("LLAMAR",F17)),ISNUMBER(SEARCH("ABONO",J17)),EXACT(L17,"P"),EXACT(F17,"P")),"Pendiente / Compromiso","Sin gestionar")))) -> Sin gestionar | P17: =IF(B17="","",IF(E17="","Sin definir",IF(ISNUMBER(SEARCH("ITIL",E17)),"ITIL",IF(ISNUMBER(SEARCH("ISO 27001",E17)),"ISO 27001",IF(ISNUMBER(SEARCH("ISO 42001",E17)),"ISO 42001",IF(ISNUMBER(SEARCH("ISO",E17)),"Otras ISO",IF(ISNUMBER(SEARCH("SCRUM",E17)),"SCRUM",IF(ISNUMBER(SEARCH("BRIDGE",E17)),"BRIDGE",IF(ISNUMBER(SEARCH("CDS",E17)),"CDS",IF(ISNUMBER(SEARCH("TOGAF",E17)),"TOGAF",IF(ISNUMBER(SEARCH("DPI",E17)),"DPI",IF(ISNUMBER(SEARCH("DITS",E17)),"DITS",IF(ISNUMBER(SEARCH("AGILE",E17)),"AGILE",IF(ISNUMBER(SEARCH("Ciberseguridad",E17)),"Ciberseguridad","Otros")))))))))))))) -> ITIL | Q17: =IF(B17="","",IF(ISNUMBER(K17),IF(K17<=3,"1-3 meses",IF(K17<=6,"4-6 meses","+6 meses")),"Sin dato registrado")) -> Sin dato registrado | R17: =IF(OR(B17="",M17=""),"",RANK(M17,$M$3:$M$306)+COUNTIF($M$3:M17,M17)-1) -> 12
A18: 18 | B18: Gabriel Enrique Moreno Pérez | D18: Sebas | E18: DITS | G18: PENDIENTE POR INGRESAR CRUSO | H18: X | I18: 3150000 | L18: QUIETO | M18: =IF(B18="","",IF(ISNUMBER(I18),I18,IFERROR(VALUE(SUBSTITUTE(SUBSTITUTE(I18,"$",""),".","")),0))) -> 3150000 | N18: =IF(B18="","",PROPER(TRIM(D18))) -> Sebas | O18: =IF(B18="","",IF(OR(ISNUMBER(SEARCH("AL DIA",L18)),ISNUMBER(SEARCH("AL DIA",F18))),"Al día",IF(OR(ISNUMBER(SEARCH("QUIETO",L18)),ISNUMBER(SEARCH("QUIETO",F18)),ISNUMBER(SEARCH("ESPERANDO",L18)),ISNUMBER(SEARCH("ESPERANDO",F18))),"Sin respuesta / Inactivo",IF(OR(ISNUMBER(SEARCH("PENDIENTE",L18)),ISNUMBER(SEARCH("PENDIENTE",F18)),ISNUMBER(SEARCH("COMPROMISO",F18)),ISNUMBER(SEARCH("COMPROMISO",L18)),ISNUMBER(SEARCH("PROCESO",F18)),ISNUMBER(SEARCH("LLAMAR",F18)),ISNUMBER(SEARCH("ABONO",J18)),EXACT(L18,"P"),EXACT(F18,"P")),"Pendiente / Compromiso","Sin gestionar")))) -> Sin respuesta / Inactivo | P18: =IF(B18="","",IF(E18="","Sin definir",IF(ISNUMBER(SEARCH("ITIL",E18)),"ITIL",IF(ISNUMBER(SEARCH("ISO 27001",E18)),"ISO 27001",IF(ISNUMBER(SEARCH("ISO 42001",E18)),"ISO 42001",IF(ISNUMBER(SEARCH("ISO",E18)),"Otras ISO",IF(ISNUMBER(SEARCH("SCRUM",E18)),"SCRUM",IF(ISNUMBER(SEARCH("BRIDGE",E18)),"BRIDGE",IF(ISNUMBER(SEARCH("CDS",E18)),"CDS",IF(ISNUMBER(SEARCH("TOGAF",E18)),"TOGAF",IF(ISNUMBER(SEARCH("DPI",E18)),"DPI",IF(ISNUMBER(SEARCH("DITS",E18)),"DITS",IF(ISNUMBER(SEARCH("AGILE",E18)),"AGILE",IF(ISNUMBER(SEARCH("Ciberseguridad",E18)),"Ciberseguridad","Otros")))))))))))))) -> DITS | Q18: =IF(B18="","",IF(ISNUMBER(K18),IF(K18<=3,"1-3 meses",IF(K18<=6,"4-6 meses","+6 meses")),"Sin dato registrado")) -> Sin dato registrado | R18: =IF(OR(B18="",M18=""),"",RANK(M18,$M$3:$M$306)+COUNTIF($M$3:M18,M18)-1) -> 1
A19: 19 | B19: Diana Carolina Acuña Serrano | D19: Carolina | E19: CDS | G19: PENDIENTE | H19: - | I19: 200000 | L19: AL DIA | M19: =IF(B19="","",IF(ISNUMBER(I19),I19,IFERROR(VALUE(SUBSTITUTE(SUBSTITUTE(I19,"$",""),".","")),0))) -> 200000 | N19: =IF(B19="","",PROPER(TRIM(D19))) -> Carolina | O19: =IF(B19="","",IF(OR(ISNUMBER(SEARCH("AL DIA",L19)),ISNUMBER(SEARCH("AL DIA",F19))),"Al día",IF(OR(ISNUMBER(SEARCH("QUIETO",L19)),ISNUMBER(SEARCH("QUIETO",F19)),ISNUMBER(SEARCH("ESPERANDO",L19)),ISNUMBER(SEARCH("ESPERANDO",F19))),"Sin respuesta / Inactivo",IF(OR(ISNUMBER(SEARCH("PENDIENTE",L19)),ISNUMBER(SEARCH("PENDIENTE",F19)),ISNUMBER(SEARCH("COMPROMISO",F19)),ISNUMBER(SEARCH("COMPROMISO",L19)),ISNUMBER(SEARCH("PROCESO",F19)),ISNUMBER(SEARCH("LLAMAR",F19)),ISNUMBER(SEARCH("ABONO",J19)),EXACT(L19,"P"),EXACT(F19,"P")),"Pendiente / Compromiso","Sin gestionar")))) -> Al día | P19: =IF(B19="","",IF(E19="","Sin definir",IF(ISNUMBER(SEARCH("ITIL",E19)),"ITIL",IF(ISNUMBER(SEARCH("ISO 27001",E19)),"ISO 27001",IF(ISNUMBER(SEARCH("ISO 42001",E19)),"ISO 42001",IF(ISNUMBER(SEARCH("ISO",E19)),"Otras ISO",IF(ISNUMBER(SEARCH("SCRUM",E19)),"SCRUM",IF(ISNUMBER(SEARCH("BRIDGE",E19)),"BRIDGE",IF(ISNUMBER(SEARCH("CDS",E19)),"CDS",IF(ISNUMBER(SEARCH("TOGAF",E19)),"TOGAF",IF(ISNUMBER(SEARCH("DPI",E19)),"DPI",IF(ISNUMBER(SEARCH("DITS",E19)),"DITS",IF(ISNUMBER(SEARCH("AGILE",E19)),"AGILE",IF(ISNUMBER(SEARCH("Ciberseguridad",E19)),"Ciberseguridad","Otros")))))))))))))) -> CDS | Q19: =IF(B19="","",IF(ISNUMBER(K19),IF(K19<=3,"1-3 meses",IF(K19<=6,"4-6 meses","+6 meses")),"Sin dato registrado")) -> Sin dato registrado | R19: =IF(OR(B19="",M19=""),"",RANK(M19,$M$3:$M$306)+COUNTIF($M$3:M19,M19)-1) -> 59
A20: 20 | B20: Jhon Isaias Muñoz Remolina | D20: Ximena | E20: CDS | G20: COMPROMISO DE PAGO | H20: x | I20: 2390000 | L20: Pendiente X FECHA | M20: =IF(B20="","",IF(ISNUMBER(I20),I20,IFERROR(VALUE(SUBSTITUTE(SUBSTITUTE(I20,"$",""),".","")),0))) -> 2390000 | N20: =IF(B20="","",PROPER(TRIM(D20))) -> Ximena | O20: =IF(B20="","",IF(OR(ISNUMBER(SEARCH("AL DIA",L20)),ISNUMBER(SEARCH("AL DIA",F20))),"Al día",IF(OR(ISNUMBER(SEARCH("QUIETO",L20)),ISNUMBER(SEARCH("QUIETO",F20)),ISNUMBER(SEARCH("ESPERANDO",L20)),ISNUMBER(SEARCH("ESPERANDO",F20))),"Sin respuesta / Inactivo",IF(OR(ISNUMBER(SEARCH("PENDIENTE",L20)),ISNUMBER(SEARCH("PENDIENTE",F20)),ISNUMBER(SEARCH("COMPROMISO",F20)),ISNUMBER(SEARCH("COMPROMISO",L20)),ISNUMBER(SEARCH("PROCESO",F20)),ISNUMBER(SEARCH("LLAMAR",F20)),ISNUMBER(SEARCH("ABONO",J20)),EXACT(L20,"P"),EXACT(F20,"P")),"Pendiente / Compromiso","Sin gestionar")))) -> Pendiente / Compromiso | P20: =IF(B20="","",IF(E20="","Sin definir",IF(ISNUMBER(SEARCH("ITIL",E20)),"ITIL",IF(ISNUMBER(SEARCH("ISO 27001",E20)),"ISO 27001",IF(ISNUMBER(SEARCH("ISO 42001",E20)),"ISO 42001",IF(ISNUMBER(SEARCH("ISO",E20)),"Otras ISO",IF(ISNUMBER(SEARCH("SCRUM",E20)),"SCRUM",IF(ISNUMBER(SEARCH("BRIDGE",E20)),"BRIDGE",IF(ISNUMBER(SEARCH("CDS",E20)),"CDS",IF(ISNUMBER(SEARCH("TOGAF",E20)),"TOGAF",IF(ISNUMBER(SEARCH("DPI",E20)),"DPI",IF(ISNUMBER(SEARCH("DITS",E20)),"DITS",IF(ISNUMBER(SEARCH("AGILE",E20)),"AGILE",IF(ISNUMBER(SEARCH("Ciberseguridad",E20)),"Ciberseguridad","Otros")))))))))))))) -> CDS | Q20: =IF(B20="","",IF(ISNUMBER(K20),IF(K20<=3,"1-3 meses",IF(K20<=6,"4-6 meses","+6 meses")),"Sin dato registrado")) -> Sin dato registrado | R20: =IF(OR(B20="",M20=""),"",RANK(M20,$M$3:$M$306)+COUNTIF($M$3:M20,M20)-1) -> 2
A21: 21 | B21: Lady Marlene Gallego Montoya | D21: Ximena | E21: CDS | G21: COMPROMISO DE PAGO | H21: X | I21: 1000000 | J21: ABONO 30 ABR | L21: Pendiente X FECHA | M21: =IF(B21="","",IF(ISNUMBER(I21),I21,IFERROR(VALUE(SUBSTITUTE(SUBSTITUTE(I21,"$",""),".","")),0))) -> 1000000 | N21: =IF(B21="","",PROPER(TRIM(D21))) -> Ximena | O21: =IF(B21="","",IF(OR(ISNUMBER(SEARCH("AL DIA",L21)),ISNUMBER(SEARCH("AL DIA",F21))),"Al día",IF(OR(ISNUMBER(SEARCH("QUIETO",L21)),ISNUMBER(SEARCH("QUIETO",F21)),ISNUMBER(SEARCH("ESPERANDO",L21)),ISNUMBER(SEARCH("ESPERANDO",F21))),"Sin respuesta / Inactivo",IF(OR(ISNUMBER(SEARCH("PENDIENTE",L21)),ISNUMBER(SEARCH("PENDIENTE",F21)),ISNUMBER(SEARCH("COMPROMISO",F21)),ISNUMBER(SEARCH("COMPROMISO",L21)),ISNUMBER(SEARCH("PROCESO",F21)),ISNUMBER(SEARCH("LLAMAR",F21)),ISNUMBER(SEARCH("ABONO",J21)),EXACT(L21,"P"),EXACT(F21,"P")),"Pendiente / Compromiso","Sin gestionar")))) -> Pendiente / Compromiso | P21: =IF(B21="","",IF(E21="","Sin definir",IF(ISNUMBER(SEARCH("ITIL",E21)),"ITIL",IF(ISNUMBER(SEARCH("ISO 27001",E21)),"ISO 27001",IF(ISNUMBER(SEARCH("ISO 42001",E21)),"ISO 42001",IF(ISNUMBER(SEARCH("ISO",E21)),"Otras ISO",IF(ISNUMBER(SEARCH("SCRUM",E21)),"SCRUM",IF(ISNUMBER(SEARCH("BRIDGE",E21)),"BRIDGE",IF(ISNUMBER(SEARCH("CDS",E21)),"CDS",IF(ISNUMBER(SEARCH("TOGAF",E21)),"TOGAF",IF(ISNUMBER(SEARCH("DPI",E21)),"DPI",IF(ISNUMBER(SEARCH("DITS",E21)),"DITS",IF(ISNUMBER(SEARCH("AGILE",E21)),"AGILE",IF(ISNUMBER(SEARCH("Ciberseguridad",E21)),"Ciberseguridad","Otros")))))))))))))) -> CDS | Q21: =IF(B21="","",IF(ISNUMBER(K21),IF(K21<=3,"1-3 meses",IF(K21<=6,"4-6 meses","+6 meses")),"Sin dato registrado")) -> Sin dato registrado | R21: =IF(OR(B21="",M21=""),"",RANK(M21,$M$3:$M$306)+COUNTIF($M$3:M21,M21)-1) -> 19
A22: 22 | B22: Jhon Edison Puerto Jiménez | D22: Carolina | E22: ITIL 4 Fundamentos | G22: SYNERGY | H22: HASTA 30 MAY | I22: 2050000 | M22: =IF(B22="","",IF(ISNUMBER(I22),I22,IFERROR(VALUE(SUBSTITUTE(SUBSTITUTE(I22,"$",""),".","")),0))) -> 2050000 | N22: =IF(B22="","",PROPER(TRIM(D22))) -> Carolina | O22: =IF(B22="","",IF(OR(ISNUMBER(SEARCH("AL DIA",L22)),ISNUMBER(SEARCH("AL DIA",F22))),"Al día",IF(OR(ISNUMBER(SEARCH("QUIETO",L22)),ISNUMBER(SEARCH("QUIETO",F22)),ISNUMBER(SEARCH("ESPERANDO",L22)),ISNUMBER(SEARCH("ESPERANDO",F22))),"Sin respuesta / Inactivo",IF(OR(ISNUMBER(SEARCH("PENDIENTE",L22)),ISNUMBER(SEARCH("PENDIENTE",F22)),ISNUMBER(SEARCH("COMPROMISO",F22)),ISNUMBER(SEARCH("COMPROMISO",L22)),ISNUMBER(SEARCH("PROCESO",F22)),ISNUMBER(SEARCH("LLAMAR",F22)),ISNUMBER(SEARCH("ABONO",J22)),EXACT(L22,"P"),EXACT(F22,"P")),"Pendiente / Compromiso","Sin gestionar")))) -> Sin gestionar | P22: =IF(B22="","",IF(E22="","Sin definir",IF(ISNUMBER(SEARCH("ITIL",E22)),"ITIL",IF(ISNUMBER(SEARCH("ISO 27001",E22)),"ISO 27001",IF(ISNUMBER(SEARCH("ISO 42001",E22)),"ISO 42001",IF(ISNUMBER(SEARCH("ISO",E22)),"Otras ISO",IF(ISNUMBER(SEARCH("SCRUM",E22)),"SCRUM",IF(ISNUMBER(SEARCH("BRIDGE",E22)),"BRIDGE",IF(ISNUMBER(SEARCH("CDS",E22)),"CDS",IF(ISNUMBER(SEARCH("TOGAF",E22)),"TOGAF",IF(ISNUMBER(SEARCH("DPI",E22)),"DPI",IF(ISNUMBER(SEARCH("DITS",E22)),"DITS",IF(ISNUMBER(SEARCH("AGILE",E22)),"AGILE",IF(ISNUMBER(SEARCH("Ciberseguridad",E22)),"Ciberseguridad","Otros")))))))))))))) -> ITIL | Q22: =IF(B22="","",IF(ISNUMBER(K22),IF(K22<=3,"1-3 meses",IF(K22<=6,"4-6 meses","+6 meses")),"Sin dato registrado")) -> Sin dato registrado | R22: =IF(OR(B22="",M22=""),"",RANK(M22,$M$3:$M$306)+COUNTIF($M$3:M22,M22)-1) -> 3
A23: 23 | B23: JOHAN YESID MORENO SARMIENTO | D23: Carolina | E23: ITIL 4 Fundamentos | G23: P | H23: P | I23: 1850000 | J23: PAGO CON CHEQUE CESANTIAS | L23: AL DIA | M23: =IF(B23="","",IF(ISNUMBER(I23),I23,IFERROR(VALUE(SUBSTITUTE(SUBSTITUTE(I23,"$",""),".","")),0))) -> 1850000 | N23: =IF(B23="","",PROPER(TRIM(D23))) -> Carolina | O23: =IF(B23="","",IF(OR(ISNUMBER(SEARCH("AL DIA",L23)),ISNUMBER(SEARCH("AL DIA",F23))),"Al día",IF(OR(ISNUMBER(SEARCH("QUIETO",L23)),ISNUMBER(SEARCH("QUIETO",F23)),ISNUMBER(SEARCH("ESPERANDO",L23)),ISNUMBER(SEARCH("ESPERANDO",F23))),"Sin respuesta / Inactivo",IF(OR(ISNUMBER(SEARCH("PENDIENTE",L23)),ISNUMBER(SEARCH("PENDIENTE",F23)),ISNUMBER(SEARCH("COMPROMISO",F23)),ISNUMBER(SEARCH("COMPROMISO",L23)),ISNUMBER(SEARCH("PROCESO",F23)),ISNUMBER(SEARCH("LLAMAR",F23)),ISNUMBER(SEARCH("ABONO",J23)),EXACT(L23,"P"),EXACT(F23,"P")),"Pendiente / Compromiso","Sin gestionar")))) -> Al día | P23: =IF(B23="","",IF(E23="","Sin definir",IF(ISNUMBER(SEARCH("ITIL",E23)),"ITIL",IF(ISNUMBER(SEARCH("ISO 27001",E23)),"ISO 27001",IF(ISNUMBER(SEARCH("ISO 42001",E23)),"ISO 42001",IF(ISNUMBER(SEARCH("ISO",E23)),"Otras ISO",IF(ISNUMBER(SEARCH("SCRUM",E23)),"SCRUM",IF(ISNUMBER(SEARCH("BRIDGE",E23)),"BRIDGE",IF(ISNUMBER(SEARCH("CDS",E23)),"CDS",IF(ISNUMBER(SEARCH("TOGAF",E23)),"TOGAF",IF(ISNUMBER(SEARCH("DPI",E23)),"DPI",IF(ISNUMBER(SEARCH("DITS",E23)),"DITS",IF(ISNUMBER(SEARCH("AGILE",E23)),"AGILE",IF(ISNUMBER(SEARCH("Ciberseguridad",E23)),"Ciberseguridad","Otros")))))))))))))) -> ITIL | Q23: =IF(B23="","",IF(ISNUMBER(K23),IF(K23<=3,"1-3 meses",IF(K23<=6,"4-6 meses","+6 meses")),"Sin dato registrado")) -> Sin dato registrado | R23: =IF(OR(B23="",M23=""),"",RANK(M23,$M$3:$M$306)+COUNTIF($M$3:M23,M23)-1) -> 5
A24: 22 | B24: Cesar Augusto Ramirez | D24: Ximena | E24: DPI | G24: P | I24: 1950000 | L24: ESPERANDO CER FUNDAMENTOS | M24: =IF(B24="","",IF(ISNUMBER(I24),I24,IFERROR(VALUE(SUBSTITUTE(SUBSTITUTE(I24,"$",""),".","")),0))) -> 1950000 | N24: =IF(B24="","",PROPER(TRIM(D24))) -> Ximena | O24: =IF(B24="","",IF(OR(ISNUMBER(SEARCH("AL DIA",L24)),ISNUMBER(SEARCH("AL DIA",F24))),"Al día",IF(OR(ISNUMBER(SEARCH("QUIETO",L24)),ISNUMBER(SEARCH("QUIETO",F24)),ISNUMBER(SEARCH("ESPERANDO",L24)),ISNUMBER(SEARCH("ESPERANDO",F24))),"Sin respuesta / Inactivo",IF(OR(ISNUMBER(SEARCH("PENDIENTE",L24)),ISNUMBER(SEARCH("PENDIENTE",F24)),ISNUMBER(SEARCH("COMPROMISO",F24)),ISNUMBER(SEARCH("COMPROMISO",L24)),ISNUMBER(SEARCH("PROCESO",F24)),ISNUMBER(SEARCH("LLAMAR",F24)),ISNUMBER(SEARCH("ABONO",J24)),EXACT(L24,"P"),EXACT(F24,"P")),"Pendiente / Compromiso","Sin gestionar")))) -> Sin respuesta / Inactivo | P24: =IF(B24="","",IF(E24="","Sin definir",IF(ISNUMBER(SEARCH("ITIL",E24)),"ITIL",IF(ISNUMBER(SEARCH("ISO 27001",E24)),"ISO 27001",IF(ISNUMBER(SEARCH("ISO 42001",E24)),"ISO 42001",IF(ISNUMBER(SEARCH("ISO",E24)),"Otras ISO",IF(ISNUMBER(SEARCH("SCRUM",E24)),"SCRUM",IF(ISNUMBER(SEARCH("BRIDGE",E24)),"BRIDGE",IF(ISNUMBER(SEARCH("CDS",E24)),"CDS",IF(ISNUMBER(SEARCH("TOGAF",E24)),"TOGAF",IF(ISNUMBER(SEARCH("DPI",E24)),"DPI",IF(ISNUMBER(SEARCH("DITS",E24)),"DITS",IF(ISNUMBER(SEARCH("AGILE",E24)),"AGILE",IF(ISNUMBER(SEARCH("Ciberseguridad",E24)),"Ciberseguridad","Otros")))))))))))))) -> DPI | Q24: =IF(B24="","",IF(ISNUMBER(K24),IF(K24<=3,"1-3 meses",IF(K24<=6,"4-6 meses","+6 meses")),"Sin dato registrado")) -> Sin dato registrado | R24: =IF(OR(B24="",M24=""),"",RANK(M24,$M$3:$M$306)+COUNTIF($M$3:M24,M24)-1) -> 4
A25: 22 | M25: =IF(B25="","",IF(ISNUMBER(I25),I25,IFERROR(VALUE(SUBSTITUTE(SUBSTITUTE(I25,"$",""),".","")),0))) | N25: =IF(B25="","",PROPER(TRIM(D25))) | O25: =IF(B25="","",IF(OR(ISNUMBER(SEARCH("AL DIA",L25)),ISNUMBER(SEARCH("AL DIA",F25))),"Al día",IF(OR(ISNUMBER(SEARCH("QUIETO",L25)),ISNUMBER(SEARCH("QUIETO",F25)),ISNUMBER(SEARCH("ESPERANDO",L25)),ISNUMBER(SEARCH("ESPERANDO",F25))),"Sin respuesta / Inactivo",IF(OR(ISNUMBER(SEARCH("PENDIENTE",L25)),ISNUMBER(SEARCH("PENDIENTE",F25)),ISNUMBER(SEARCH("COMPROMISO",F25)),ISNUMBER(SEARCH("COMPROMISO",L25)),ISNUMBER(SEARCH("PROCESO",F25)),ISNUMBER(SEARCH("LLAMAR",F25)),ISNUMBER(SEARCH("ABONO",J25)),EXACT(L25,"P"),EXACT(F25,"P")),"Pendiente / Compromiso","Sin gestionar")))) | P25: =IF(B25="","",IF(E25="","Sin definir",IF(ISNUMBER(SEARCH("ITIL",E25)),"ITIL",IF(ISNUMBER(SEARCH("ISO 27001",E25)),"ISO 27001",IF(ISNUMBER(SEARCH("ISO 42001",E25)),"ISO 42001",IF(ISNUMBER(SEARCH("ISO",E25)),"Otras ISO",IF(ISNUMBER(SEARCH("SCRUM",E25)),"SCRUM",IF(ISNUMBER(SEARCH("BRIDGE",E25)),"BRIDGE",IF(ISNUMBER(SEARCH("CDS",E25)),"CDS",IF(ISNUMBER(SEARCH("TOGAF",E25)),"TOGAF",IF(ISNUMBER(SEARCH("DPI",E25)),"DPI",IF(ISNUMBER(SEARCH("DITS",E25)),"DITS",IF(ISNUMBER(SEARCH("AGILE",E25)),"AGILE",IF(ISNUMBER(SEARCH("Ciberseguridad",E25)),"Ciberseguridad","Otros")))))))))))))) | Q25: =IF(B25="","",IF(ISNUMBER(K25),IF(K25<=3,"1-3 meses",IF(K25<=6,"4-6 meses","+6 meses")),"Sin dato registrado")) | R25: =IF(OR(B25="",M25=""),"",RANK(M25,$M$3:$M$306)+COUNTIF($M$3:M25,M25)-1)
A26: 22 | M26: =IF(B26="","",IF(ISNUMBER(I26),I26,IFERROR(VALUE(SUBSTITUTE(SUBSTITUTE(I26,"$",""),".","")),0))) | N26: =IF(B26="","",PROPER(TRIM(D26))) | O26: =IF(B26="","",IF(OR(ISNUMBER(SEARCH("AL DIA",L26)),ISNUMBER(SEARCH("AL DIA",F26))),"Al día",IF(OR(ISNUMBER(SEARCH("QUIETO",L26)),ISNUMBER(SEARCH("QUIETO",F26)),ISNUMBER(SEARCH("ESPERANDO",L26)),ISNUMBER(SEARCH("ESPERANDO",F26))),"Sin respuesta / Inactivo",IF(OR(ISNUMBER(SEARCH("PENDIENTE",L26)),ISNUMBER(SEARCH("PENDIENTE",F26)),ISNUMBER(SEARCH("COMPROMISO",F26)),ISNUMBER(SEARCH("COMPROMISO",L26)),ISNUMBER(SEARCH("PROCESO",F26)),ISNUMBER(SEARCH("LLAMAR",F26)),ISNUMBER(SEARCH("ABONO",J26)),EXACT(L26,"P"),EXACT(F26,"P")),"Pendiente / Compromiso","Sin gestionar")))) | P26: =IF(B26="","",IF(E26="","Sin definir",IF(ISNUMBER(SEARCH("ITIL",E26)),"ITIL",IF(ISNUMBER(SEARCH("ISO 27001",E26)),"ISO 27001",IF(ISNUMBER(SEARCH("ISO 42001",E26)),"ISO 42001",IF(ISNUMBER(SEARCH("ISO",E26)),"Otras ISO",IF(ISNUMBER(SEARCH("SCRUM",E26)),"SCRUM",IF(ISNUMBER(SEARCH("BRIDGE",E26)),"BRIDGE",IF(ISNUMBER(SEARCH("CDS",E26)),"CDS",IF(ISNUMBER(SEARCH("TOGAF",E26)),"TOGAF",IF(ISNUMBER(SEARCH("DPI",E26)),"DPI",IF(ISNUMBER(SEARCH("DITS",E26)),"DITS",IF(ISNUMBER(SEARCH("AGILE",E26)),"AGILE",IF(ISNUMBER(SEARCH("Ciberseguridad",E26)),"Ciberseguridad","Otros")))))))))))))) | Q26: =IF(B26="","",IF(ISNUMBER(K26),IF(K26<=3,"1-3 meses",IF(K26<=6,"4-6 meses","+6 meses")),"Sin dato registrado")) | R26: =IF(OR(B26="",M26=""),"",RANK(M26,$M$3:$M$306)+COUNTIF($M$3:M26,M26)-1)
A27: 22 | M27: =IF(B27="","",IF(ISNUMBER(I27),I27,IFERROR(VALUE(SUBSTITUTE(SUBSTITUTE(I27,"$",""),".","")),0))) | N27: =IF(B27="","",PROPER(TRIM(D27))) | O27: =IF(B27="","",IF(OR(ISNUMBER(SEARCH("AL DIA",L27)),ISNUMBER(SEARCH("AL DIA",F27))),"Al día",IF(OR(ISNUMBER(SEARCH("QUIETO",L27)),ISNUMBER(SEARCH("QUIETO",F27)),ISNUMBER(SEARCH("ESPERANDO",L27)),ISNUMBER(SEARCH("ESPERANDO",F27))),"Sin respuesta / Inactivo",IF(OR(ISNUMBER(SEARCH("PENDIENTE",L27)),ISNUMBER(SEARCH("PENDIENTE",F27)),ISNUMBER(SEARCH("COMPROMISO",F27)),ISNUMBER(SEARCH("COMPROMISO",L27)),ISNUMBER(SEARCH("PROCESO",F27)),ISNUMBER(SEARCH("LLAMAR",F27)),ISNUMBER(SEARCH("ABONO",J27)),EXACT(L27,"P"),EXACT(F27,"P")),"Pendiente / Compromiso","Sin gestionar")))) | P27: =IF(B27="","",IF(E27="","Sin definir",IF(ISNUMBER(SEARCH("ITIL",E27)),"ITIL",IF(ISNUMBER(SEARCH("ISO 27001",E27)),"ISO 27001",IF(ISNUMBER(SEARCH("ISO 42001",E27)),"ISO 42001",IF(ISNUMBER(SEARCH("ISO",E27)),"Otras ISO",IF(ISNUMBER(SEARCH("SCRUM",E27)),"SCRUM",IF(ISNUMBER(SEARCH("BRIDGE",E27)),"BRIDGE",IF(ISNUMBER(SEARCH("CDS",E27)),"CDS",IF(ISNUMBER(SEARCH("TOGAF",E27)),"TOGAF",IF(ISNUMBER(SEARCH("DPI",E27)),"DPI",IF(ISNUMBER(SEARCH("DITS",E27)),"DITS",IF(ISNUMBER(SEARCH("AGILE",E27)),"AGILE",IF(ISNUMBER(SEARCH("Ciberseguridad",E27)),"Ciberseguridad","Otros")))))))))))))) | Q27: =IF(B27="","",IF(ISNUMBER(K27),IF(K27<=3,"1-3 meses",IF(K27<=6,"4-6 meses","+6 meses")),"Sin dato registrado")) | R27: =IF(OR(B27="",M27=""),"",RANK(M27,$M$3:$M$306)+COUNTIF($M$3:M27,M27)-1)
A28: 22 | M28: =IF(B28="","",IF(ISNUMBER(I28),I28,IFERROR(VALUE(SUBSTITUTE(SUBSTITUTE(I28,"$",""),".","")),0))) | N28: =IF(B28="","",PROPER(TRIM(D28))) | O28: =IF(B28="","",IF(OR(ISNUMBER(SEARCH("AL DIA",L28)),ISNUMBER(SEARCH("AL DIA",F28))),"Al día",IF(OR(ISNUMBER(SEARCH("QUIETO",L28)),ISNUMBER(SEARCH("QUIETO",F28)),ISNUMBER(SEARCH("ESPERANDO",L28)),ISNUMBER(SEARCH("ESPERANDO",F28))),"Sin respuesta / Inactivo",IF(OR(ISNUMBER(SEARCH("PENDIENTE",L28)),ISNUMBER(SEARCH("PENDIENTE",F28)),ISNUMBER(SEARCH("COMPROMISO",F28)),ISNUMBER(SEARCH("COMPROMISO",L28)),ISNUMBER(SEARCH("PROCESO",F28)),ISNUMBER(SEARCH("LLAMAR",F28)),ISNUMBER(SEARCH("ABONO",J28)),EXACT(L28,"P"),EXACT(F28,"P")),"Pendiente / Compromiso","Sin gestionar")))) | P28: =IF(B28="","",IF(E28="","Sin definir",IF(ISNUMBER(SEARCH("ITIL",E28)),"ITIL",IF(ISNUMBER(SEARCH("ISO 27001",E28)),"ISO 27001",IF(ISNUMBER(SEARCH("ISO 42001",E28)),"ISO 42001",IF(ISNUMBER(SEARCH("ISO",E28)),"Otras ISO",IF(ISNUMBER(SEARCH("SCRUM",E28)),"SCRUM",IF(ISNUMBER(SEARCH("BRIDGE",E28)),"BRIDGE",IF(ISNUMBER(SEARCH("CDS",E28)),"CDS",IF(ISNUMBER(SEARCH("TOGAF",E28)),"TOGAF",IF(ISNUMBER(SEARCH("DPI",E28)),"DPI",IF(ISNUMBER(SEARCH("DITS",E28)),"DITS",IF(ISNUMBER(SEARCH("AGILE",E28)),"AGILE",IF(ISNUMBER(SEARCH("Ciberseguridad",E28)),"Ciberseguridad","Otros")))))))))))))) | Q28: =IF(B28="","",IF(ISNUMBER(K28),IF(K28<=3,"1-3 meses",IF(K28<=6,"4-6 meses","+6 meses")),"Sin dato registrado")) | R28: =IF(OR(B28="",M28=""),"",RANK(M28,$M$3:$M$306)+COUNTIF($M$3:M28,M28)-1)
A29: 22 | M29: =IF(B29="","",IF(ISNUMBER(I29),I29,IFERROR(VALUE(SUBSTITUTE(SUBSTITUTE(I29,"$",""),".","")),0))) | N29: =IF(B29="","",PROPER(TRIM(D29))) | O29: =IF(B29="","",IF(OR(ISNUMBER(SEARCH("AL DIA",L29)),ISNUMBER(SEARCH("AL DIA",F29))),"Al día",IF(OR(ISNUMBER(SEARCH("QUIETO",L29)),ISNUMBER(SEARCH("QUIETO",F29)),ISNUMBER(SEARCH("ESPERANDO",L29)),ISNUMBER(SEARCH("ESPERANDO",F29))),"Sin respuesta / Inactivo",IF(OR(ISNUMBER(SEARCH("PENDIENTE",L29)),ISNUMBER(SEARCH("PENDIENTE",F29)),ISNUMBER(SEARCH("COMPROMISO",F29)),ISNUMBER(SEARCH("COMPROMISO",L29)),ISNUMBER(SEARCH("PROCESO",F29)),ISNUMBER(SEARCH("LLAMAR",F29)),ISNUMBER(SEARCH("ABONO",J29)),EXACT(L29,"P"),EXACT(F29,"P")),"Pendiente / Compromiso","Sin gestionar")))) | P29: =IF(B29="","",IF(E29="","Sin definir",IF(ISNUMBER(SEARCH("ITIL",E29)),"ITIL",IF(ISNUMBER(SEARCH("ISO 27001",E29)),"ISO 27001",IF(ISNUMBER(SEARCH("ISO 42001",E29)),"ISO 42001",IF(ISNUMBER(SEARCH("ISO",E29)),"Otras ISO",IF(ISNUMBER(SEARCH("SCRUM",E29)),"SCRUM",IF(ISNUMBER(SEARCH("BRIDGE",E29)),"BRIDGE",IF(ISNUMBER(SEARCH("CDS",E29)),"CDS",IF(ISNUMBER(SEARCH("TOGAF",E29)),"TOGAF",IF(ISNUMBER(SEARCH("DPI",E29)),"DPI",IF(ISNUMBER(SEARCH("DITS",E29)),"DITS",IF(ISNUMBER(SEARCH("AGILE",E29)),"AGILE",IF(ISNUMBER(SEARCH("Ciberseguridad",E29)),"Ciberseguridad","Otros")))))))))))))) | Q29: =IF(B29="","",IF(ISNUMBER(K29),IF(K29<=3,"1-3 meses",IF(K29<=6,"4-6 meses","+6 meses")),"Sin dato registrado")) | R29: =IF(OR(B29="",M29=""),"",RANK(M29,$M$3:$M$306)+COUNTIF($M$3:M29,M29)-1)
A30: 22 | M30: =IF(B30="","",IF(ISNUMBER(I30),I30,IFERROR(VALUE(SUBSTITUTE(SUBSTITUTE(I30,"$",""),".","")),0))) | N30: =IF(B30="","",PROPER(TRIM(D30))) | O30: =IF(B30="","",IF(OR(ISNUMBER(SEARCH("AL DIA",L30)),ISNUMBER(SEARCH("AL DIA",F30))),"Al día",IF(OR(ISNUMBER(SEARCH("QUIETO",L30)),ISNUMBER(SEARCH("QUIETO",F30)),ISNUMBER(SEARCH("ESPERANDO",L30)),ISNUMBER(SEARCH("ESPERANDO",F30))),"Sin respuesta / Inactivo",IF(OR(ISNUMBER(SEARCH("PENDIENTE",L30)),ISNUMBER(SEARCH("PENDIENTE",F30)),ISNUMBER(SEARCH("COMPROMISO",F30)),ISNUMBER(SEARCH("COMPROMISO",L30)),ISNUMBER(SEARCH("PROCESO",F30)),ISNUMBER(SEARCH("LLAMAR",F30)),ISNUMBER(SEARCH("ABONO",J30)),EXACT(L30,"P"),EXACT(F30,"P")),"Pendiente / Compromiso","Sin gestionar")))) | P30: =IF(B30="","",IF(E30="","Sin definir",IF(ISNUMBER(SEARCH("ITIL",E30)),"ITIL",IF(ISNUMBER(SEARCH("ISO 27001",E30)),"ISO 27001",IF(ISNUMBER(SEARCH("ISO 42001",E30)),"ISO 42001",IF(ISNUMBER(SEARCH("ISO",E30)),"Otras ISO",IF(ISNUMBER(SEARCH("SCRUM",E30)),"SCRUM",IF(ISNUMBER(SEARCH("BRIDGE",E30)),"BRIDGE",IF(ISNUMBER(SEARCH("CDS",E30)),"CDS",IF(ISNUMBER(SEARCH("TOGAF",E30)),"TOGAF",IF(ISNUMBER(SEARCH("DPI",E30)),"DPI",IF(ISNUMBER(SEARCH("DITS",E30)),"DITS",IF(ISNUMBER(SEARCH("AGILE",E30)),"AGILE",IF(ISNUMBER(SEARCH("Ciberseguridad",E30)),"Ciberseguridad","Otros")))))))))))))) | Q30: =IF(B30="","",IF(ISNUMBER(K30),IF(K30<=3,"1-3 meses",IF(K30<=6,"4-6 meses","+6 meses")),"Sin dato registrado")) | R30: =IF(OR(B30="",M30=""),"",RANK(M30,$M$3:$M$306)+COUNTIF($M$3:M30,M30)-1)
A31: 22 | M31: =IF(B31="","",IF(ISNUMBER(I31),I31,IFERROR(VALUE(SUBSTITUTE(SUBSTITUTE(I31,"$",""),".","")),0))) | N31: =IF(B31="","",PROPER(TRIM(D31))) | O31: =IF(B31="","",IF(OR(ISNUMBER(SEARCH("AL DIA",L31)),ISNUMBER(SEARCH("AL DIA",F31))),"Al día",IF(OR(ISNUMBER(SEARCH("QUIETO",L31)),ISNUMBER(SEARCH("QUIETO",F31)),ISNUMBER(SEARCH("ESPERANDO",L31)),ISNUMBER(SEARCH("ESPERANDO",F31))),"Sin respuesta / Inactivo",IF(OR(ISNUMBER(SEARCH("PENDIENTE",L31)),ISNUMBER(SEARCH("PENDIENTE",F31)),ISNUMBER(SEARCH("COMPROMISO",F31)),ISNUMBER(SEARCH("COMPROMISO",L31)),ISNUMBER(SEARCH("PROCESO",F31)),ISNUMBER(SEARCH("LLAMAR",F31)),ISNUMBER(SEARCH("ABONO",J31)),EXACT(L31,"P"),EXACT(F31,"P")),"Pendiente / Compromiso","Sin gestionar")))) | P31: =IF(B31="","",IF(E31="","Sin definir",IF(ISNUMBER(SEARCH("ITIL",E31)),"ITIL",IF(ISNUMBER(SEARCH("ISO 27001",E31)),"ISO 27001",IF(ISNUMBER(SEARCH("ISO 42001",E31)),"ISO 42001",IF(ISNUMBER(SEARCH("ISO",E31)),"Otras ISO",IF(ISNUMBER(SEARCH("SCRUM",E31)),"SCRUM",IF(ISNUMBER(SEARCH("BRIDGE",E31)),"BRIDGE",IF(ISNUMBER(SEARCH("CDS",E31)),"CDS",IF(ISNUMBER(SEARCH("TOGAF",E31)),"TOGAF",IF(ISNUMBER(SEARCH("DPI",E31)),"DPI",IF(ISNUMBER(SEARCH("DITS",E31)),"DITS",IF(ISNUMBER(SEARCH("AGILE",E31)),"AGILE",IF(ISNUMBER(SEARCH("Ciberseguridad",E31)),"Ciberseguridad","Otros")))))))))))))) | Q31: =IF(B31="","",IF(ISNUMBER(K31),IF(K31<=3,"1-3 meses",IF(K31<=6,"4-6 meses","+6 meses")),"Sin dato registrado")) | R31: =IF(OR(B31="",M31=""),"",RANK(M31,$M$3:$M$306)+COUNTIF($M$3:M31,M31)-1)
A32: 22 | M32: =IF(B32="","",IF(ISNUMBER(I32),I32,IFERROR(VALUE(SUBSTITUTE(SUBSTITUTE(I32,"$",""),".","")),0))) | N32: =IF(B32="","",PROPER(TRIM(D32))) | O32: =IF(B32="","",IF(OR(ISNUMBER(SEARCH("AL DIA",L32)),ISNUMBER(SEARCH("AL DIA",F32))),"Al día",IF(OR(ISNUMBER(SEARCH("QUIETO",L32)),ISNUMBER(SEARCH("QUIETO",F32)),ISNUMBER(SEARCH("ESPERANDO",L32)),ISNUMBER(SEARCH("ESPERANDO",F32))),"Sin respuesta / Inactivo",IF(OR(ISNUMBER(SEARCH("PENDIENTE",L32)),ISNUMBER(SEARCH("PENDIENTE",F32)),ISNUMBER(SEARCH("COMPROMISO",F32)),ISNUMBER(SEARCH("COMPROMISO",L32)),ISNUMBER(SEARCH("PROCESO",F32)),ISNUMBER(SEARCH("LLAMAR",F32)),ISNUMBER(SEARCH("ABONO",J32)),EXACT(L32,"P"),EXACT(F32,"P")),"Pendiente / Compromiso","Sin gestionar")))) | P32: =IF(B32="","",IF(E32="","Sin definir",IF(ISNUMBER(SEARCH("ITIL",E32)),"ITIL",IF(ISNUMBER(SEARCH("ISO 27001",E32)),"ISO 27001",IF(ISNUMBER(SEARCH("ISO 42001",E32)),"ISO 42001",IF(ISNUMBER(SEARCH("ISO",E32)),"Otras ISO",IF(ISNUMBER(SEARCH("SCRUM",E32)),"SCRUM",IF(ISNUMBER(SEARCH("BRIDGE",E32)),"BRIDGE",IF(ISNUMBER(SEARCH("CDS",E32)),"CDS",IF(ISNUMBER(SEARCH("TOGAF",E32)),"TOGAF",IF(ISNUMBER(SEARCH("DPI",E32)),"DPI",IF(ISNUMBER(SEARCH("DITS",E32)),"DITS",IF(ISNUMBER(SEARCH("AGILE",E32)),"AGILE",IF(ISNUMBER(SEARCH("Ciberseguridad",E32)),"Ciberseguridad","Otros")))))))))))))) | Q32: =IF(B32="","",IF(ISNUMBER(K32),IF(K32<=3,"1-3 meses",IF(K32<=6,"4-6 meses","+6 meses")),"Sin dato registrado")) | R32: =IF(OR(B32="",M32=""),"",RANK(M32,$M$3:$M$306)+COUNTIF($M$3:M32,M32)-1)
A33: 22 | M33: =IF(B33="","",IF(ISNUMBER(I33),I33,IFERROR(VALUE(SUBSTITUTE(SUBSTITUTE(I33,"$",""),".","")),0))) | N33: =IF(B33="","",PROPER(TRIM(D33))) | O33: =IF(B33="","",IF(OR(ISNUMBER(SEARCH("AL DIA",L33)),ISNUMBER(SEARCH("AL DIA",F33))),"Al día",IF(OR(ISNUMBER(SEARCH("QUIETO",L33)),ISNUMBER(SEARCH("QUIETO",F33)),ISNUMBER(SEARCH("ESPERANDO",L33)),ISNUMBER(SEARCH("ESPERANDO",F33))),"Sin respuesta / Inactivo",IF(OR(ISNUMBER(SEARCH("PENDIENTE",L33)),ISNUMBER(SEARCH("PENDIENTE",F33)),ISNUMBER(SEARCH("COMPROMISO",F33)),ISNUMBER(SEARCH("COMPROMISO",L33)),ISNUMBER(SEARCH("PROCESO",F33)),ISNUMBER(SEARCH("LLAMAR",F33)),ISNUMBER(SEARCH("ABONO",J33)),EXACT(L33,"P"),EXACT(F33,"P")),"Pendiente / Compromiso","Sin gestionar")))) | P33: =IF(B33="","",IF(E33="","Sin definir",IF(ISNUMBER(SEARCH("ITIL",E33)),"ITIL",IF(ISNUMBER(SEARCH("ISO 27001",E33)),"ISO 27001",IF(ISNUMBER(SEARCH("ISO 42001",E33)),"ISO 42001",IF(ISNUMBER(SEARCH("ISO",E33)),"Otras ISO",IF(ISNUMBER(SEARCH("SCRUM",E33)),"SCRUM",IF(ISNUMBER(SEARCH("BRIDGE",E33)),"BRIDGE",IF(ISNUMBER(SEARCH("CDS",E33)),"CDS",IF(ISNUMBER(SEARCH("TOGAF",E33)),"TOGAF",IF(ISNUMBER(SEARCH("DPI",E33)),"DPI",IF(ISNUMBER(SEARCH("DITS",E33)),"DITS",IF(ISNUMBER(SEARCH("AGILE",E33)),"AGILE",IF(ISNUMBER(SEARCH("Ciberseguridad",E33)),"Ciberseguridad","Otros")))))))))))))) | Q33: =IF(B33="","",IF(ISNUMBER(K33),IF(K33<=3,"1-3 meses",IF(K33<=6,"4-6 meses","+6 meses")),"Sin dato registrado")) | R33: =IF(OR(B33="",M33=""),"",RANK(M33,$M$3:$M$306)+COUNTIF($M$3:M33,M33)-1)
